Workbook

Sheet 00_통제변수
A1: 다이소몰 매출 시뮬레이션 — 통제변수
A2: 파란 글씨 셀만 수정하십시오. 나머지는 수식입니다. 값을 바꾸면 4개 시나리오 시트와 요약이 모두 따라 움직입니다.
A4: 공통 가정
A5: 시작 연월 | B5: 2027-01 | D5: 시뮬레이션 시작 시점
A6: 시뮬 개월수 | B6: 60 | D6: 2027-01 ~ 2031-12
A7: 2026.12 누적 구매고객 (만명) | B7: 406 | D7: 2026-08 실측 358.5만 + 9~12월 신규 추정
A8: 택배 외 채널 비중 | B8: 0.062 | D8: 픽업·대량·오늘배송 합계 (2026 1~8월 실측)
A9: 회원배수 — 시작 (2027-01) | B9: 2.58 | D9: 회원 926만 ÷ 누적 구매고객 358.5만 (2026-08 실측)
A10: 회원배수 — 종료 (2031-12) | B10: 1.8 | D10: 구매 전환 비중이 높아지며 배수가 낮아진다는 가정
A11: 매출 보정계수 | B11: 1 | D11: 모델 산출을 사업계획에 맞출 때 사용 (1.00 = 보정 없음)
A14: 시나리오별 가정
A15: 구분 | C15: 1 | D15: 2 | E15: 3 | F15: 4 | H15: 설명
A16: 신규 구매고객 시작값 (만명/월) | C16: 12 | D16: 12 | E16: 12 | F16: 12 | H16: 2027-01 월 신규 택배 구매고객. 실측 9~13.4만 범위
A17: 신규 구매고객 월 증감률 | C17: -0.005 | D17: -0.001 | E17: -0.003 | F17: -0.005 | H17: 음수 = 감쇠. 신규 서비스가 많을수록 감쇠가 작다는 가정
A18: 잔존율 — 시작 | C18: 0.111 | D18: 0.111 | E18: 0.111 | F18: 0.111 | H18: 누적 구매고객 중 당월 재구매 비율. M4~M12 실측
A19: 잔존율 — 목표 | C19: 0.105 | D19: 0.15 | E19: 0.12 | F19: 0.105 | H19: ②는 가입 첫달 수준(15%), ③은 중간 수준(13%)
A20: 잔존율 — 성장 시작 월차 | C20: 1 | D20: 6 | E20: 6 | F20: 1 | H20: 6 = 2027년 6월 (세종 안정화 시점)
A21: 잔존율 — 목표 도달 개월수 | C21: 1 | D21: 42 | E21: 48 | F21: 1 | H21: 작을수록 빨리 올라간다. 42 = 2030년 11월 도달
A22: 구매빈도 — 시작 (건/월) | C22: 1.289 | D22: 1.289 | E22: 1.289 | F22: 1.289 | H22: 주문/구매고객. 33개월 고정 실측
A23: 구매빈도 — 목표 (건/월) | C23: 1.289 | D23: 1.8 | E23: 1.55 | F23: 1.289 | H23: ②는 임계 인하로 소액 주문이 늘어난다는 가정
A24: 구매빈도 — 성장 시작 월차 | C24: 1 | D24: 6 | E24: 6 | F24: 1
A25: 구매빈도 — 목표 도달 개월수 | C25: 1 | D25: 30 | E25: 48 | F25: 1
A26: 객단가 — 변경 전 (원) | C26: 31846 | D26: 31846 | E26: 31846 | F26: 31846 | H26: 택배 객단가 2026 1~8월 실측
A27: 객단가 — 변경 후 (원) | C27: 31846 | D27: 26000 | E27: 31846 | F27: 31846 | H27: ②만 무료배송 임계 2.5만원 인하로 하락
A28: 객단가 — 변경 월차 | C28: 999 | D28: =D20 -> 6 | E28: 999 | F28: 999 | H28: 12 = 2027년 12월부터 적용. 999 = 변경 없음
A31: 외국인 회원 (시나리오 ④ 전용, 현상유지에 가산)
A32: 유입 시작 월차 | B32: 9 | D32: 9 = 2027년 9월
A33: 월 신규 구매고객 (명) | B33: 10000 | D33: 매월 신규로 유입되는 외국인 구매고객
A34: 잔존율 | B34: 0.03 | D34: 내국인 11.1% 대비 크게 낮은 수준
A35: 객단가 (원) | B35: 60000 | D35: 해외배송 객단가 가정
A36: 구매빈도 (건/월) | B36: 1.05 | D36: 사실상 단발 구매
A39: 범례 및 모델 구조
A40: 파란 글씨 + 노란 채움 = 입력 셀. 이 셀만 수정하십시오.
A41: 검은 글씨 = 수식. 수정하지 마십시오.
A43: 월별 계산 순서
A44: ① 신규 구매고객 = 시작값 × (1 + 월증감률)^(월차-1)
A45: ② 누적 구매고객 = 전월 누적 + 당월 신규
A46: ③ 활동 구매고객 = 당월 신규 + 전월 누적 × 잔존율
A47: ④ 구매건수 = 활동 구매고객 × 구매빈도
A48: ⑤ 택배매출 = 구매건수 × 객단가
...

Sheet 01_현상유지
A1: ① 현상유지
A2: 모든 값은 00_통제변수 시트에서 결정됩니다. 이 시트는 수정하지 마십시오.
A3: 월차 | B3: 연도 | C3: 월 | D3: 신규 구매고객 (만명) | E3: 누적 구매고객 (만명) | F3: 잔존율 | G3: 기존 활동 (만명) | H3: 활동 구매고객 (만명) | I3: 구매빈도 (건/월) | J3: 구매건수 (만건) | K3: 객단가 (원) | L3: 택배매출 (억원) | M3: 총매출 (억원) | N3: 회원수 (만명)
A4: 1 | B4: 2027 | C4: 1 | D4: ='00_통제변수'!$C$16*(1+'00_통제변수'!$C$17)^(A4-1) -> 12 | E4: ='00_통제변수'!$B$7+D4 -> 418 | F4: ='00_통제변수'!$C$18+('00_통제변수'!$C$19-'00_통제변수'!$C$18)*MIN(1,MAX(0,(A4-'00_통제변수'!$C$20+1)/MAX(1,'00_통제변수'!$C$21))) -> 0.105 | G4: ='00_통제변수'!$B$7*F4 -> 42.63 | H4: =D4+G4 -> 54.63 | I4: ='00_통제변수'!$C$22+('00_통제변수'!$C$23-'00_통제변수'!$C$22)*MIN(1,MAX(0,(A4-'00_통제변수'!$C$24+1)/MAX(1,'00_통제변수'!$C$25))) -> 1.289 | J4: =H4*I4 -> 70.41807 | K4: =IF(A4>='00_통제변수'!$C$28,'00_통제변수'!$C$27,'00_통제변수'!$C$26) -> 31846 | L4: =J4*K4/10000 -> 224.25339 | M4: =L4/(1-'00_통제변수'!$B$8)*'00_통제변수'!$B$11 -> 239.0761 | N4: =E4*('00_통제변수'!$B$9+('00_통제변수'!$B$10-'00_통제변수'!$B$9)*(A4-1)/MAX(1,'00_통제변수'!$B$6-1)) -> 1078.44
A5: 2 | B5: 2027 | C5: 2 | D5: ='00_통제변수'!$C$16*(1+'00_통제변수'!$C$17)^(A5-1) -> 11.94 | E5: =E4+D5 -> 429.94 | F5: ='00_통제변수'!$C$18+('00_통제변수'!$C$19-'00_통제변수'!$C$18)*MIN(1,MAX(0,(A5-'00_통제변수'!$C$20+1)/MAX(1,'00_통제변수'!$C$21))) -> 0.105 | G5: =E4*F5 -> 43.89 | H5: =D5+G5 -> 55.83 | I5: ='00_통제변수'!$C$22+('00_통제변수'!$C$23-'00_통제변수'!$C$22)*MIN(1,MAX(0,(A5-'00_통제변수'!$C$24+1)/MAX(1,'00_통제변수'!$C$25))) -> 1.289 | J5: =H5*I5 -> 71.96487 | K5: =IF(A5>='00_통제변수'!$C$28,'00_통제변수'!$C$27,'00_통제변수'!$C$26) -> 31846 | L5: =J5*K5/10000 -> 229.17933 | M5: =L5/(1-'00_통제변수'!$B$8)*'00_통제변수'!$B$11 -> 244.32764 | N5: =E5*('00_통제변수'!$B$9+('00_통제변수'!$B$10-'00_통제변수'!$B$9)*(A5-1)/MAX(1,'00_통제변수'!$B$6-1)) -> 1103.5612
A6: 3 | B6: 2027 | C6: 3 | D6: ='00_통제변수'!$C$16*(1+'00_통제변수'!$C$17)^(A6-1) -> 11.8803 | E6: =E5+D6 -> 441.8203 | F6: ='00_통제변수'!$C$18+('00_통제변수'!$C$19-'00_통제변수'!$C$18)*MIN(1,MAX(0,(A6-'00_통제변수'!$C$20+1)/MAX(1,'00_통제변수'!$C$21))) -> 0.105 | G6: =E5*F6 -> 45.1437 | H6: =D6+G6 -> 57.024 | I6: ='00_통제변수'!$C$22+('00_통제변수'!$C$23-'00_통제변수'!$C$22)*MIN(1,MAX(0,(A6-'00_통제변수'!$C$24+1)/MAX(1,'00_통제변수'!$C$25))) -> 1.289 | J6: =H6*I6 -> 73.503936 | K6: =IF(A6>='00_통제변수'!$C$28,'00_통제변수'!$C$27,'00_통제변수'!$C$26) -> 31846 | L6: =J6*K6/10000 -> 234.08063 | M6: =L6/(1-'00_통제변수'!$B$8)*'00_통제변수'!$B$11 -> 249.55292 | N6: =E6*('00_통제변수'!$B$9+('00_통제변수'!$B$10-'00_통제변수'!$B$9)*(A6-1)/MAX(1,'00_통제변수'!$B$6-1)) -> 1128.2143
A7: 4 | B7: 2027 | C7: 4 | D7: ='00_통제변수'!$C$16*(1+'00_통제변수'!$C$17)^(A7-1) -> 11.820899 | E7: =E6+D7 -> 453.6412 | F7: ='00_통제변수'!$C$18+('00_통제변수'!$C$19-'00_통제변수'!$C$18)*MIN(1,MAX(0,(A7-'00_통제변수'!$C$20+1)/MAX(1,'00_통제변수'!$C$21))) -> 0.105 | G7: =E6*F7 -> 46.391131 | H7: =D7+G7 -> 58.21203 | I7: ='00_통제변수'!$C$22+('00_통제변수'!$C$23-'00_통제변수'!$C$22)*MIN(1,MAX(0,(A7-'00_통제변수'!$C$24+1)/MAX(1,'00_통제변수'!$C$25))) -> 1.289 | J7: =H7*I7 -> 75.035307 | K7: =IF(A7>='00_통제변수'!$C$28,'00_통제변수'!$C$27,'00_통제변수'!$C$26) -> 31846 | L7: =J7*K7/10000 -> 238.95744 | M7: =L7/(1-'00_통제변수'!$B$8)*'00_통제변수'!$B$11 -> 254.75207 | N7: =E7*('00_통제변수'!$B$9+('00_통제변수'!$B$10-'00_통제변수'!$B$9)*(A7-1)/MAX(1,'00_통제변수'!$B$6-1)) -> 1152.4024
A8: 5 | B8: 2027 | C8: 5 | D8: ='00_통제변수'!$C$16*(1+'00_통제변수'!$C$17)^(A8-1) -> 11.761794 | E8: =E7+D8 -> 465.40299 | F8: ='00_통제변수'!$C$18+('00_통제변수'!$C$19-'00_통제변수'!$C$18)*MIN(1,MAX(0,(A8-'00_통제변수'!$C$20+1)/MAX(1,'00_통제변수'!$C$21))) -> 0.105 | G8: =E7*F8 -> 47.632326 | H8: =D8+G8 -> 59.39412 | I8: ='00_통제변수'!$C$22+('00_통제변수'!$C$23-'00_통제변수'!$C$22)*MIN(1,MAX(0,(A8-'00_통제변수'!$C$24+1)/MAX(1,'00_통제변수'!$C$25))) -> 1.289 | J8: =H8*I8 -> 76.55902 | K8: =IF(A8>='00_통제변수'!$C$28,'00_통제변수'!$C$27,'00_통제변수'!$C$26) -> 31846 | L8: =J8*K8/10000 -> 243.80986 | M8: =L8/(1-'00_통제변수'!$B$8)*'00_통제변수'!$B$11 -> 259.92522 | N8: =E8*('00_통제변수'!$B$9+('00_통제변수'!$B$10-'00_통제변수'!$B$9)*(A8-1)/MAX(1,'00_통제변수'!$B$6-1)) -> 1176.1286
A9: 6 | B9: 2027 | C9: 6 | D9: ='00_통제변수'!$C$16*(1+'00_통제변수'!$C$17)^(A9-1) -> 11.702985 | E9: =E8+D9 -> 477.10598 | F9: ='00_통제변수'!$C$18+('00_통제변수'!$C$19-'00_통제변수'!$C$18)*MIN(1,MAX(0,(A9-'00_통제변수'!$C$20+1)/MAX(1,'00_통제변수'!$C$21))) -> 0.105 | G9: =E8*F9 -> 48.867314 | H9: =D9+G9 -> 60.570299 | I9: ='00_통제변수'!$C$22+('00_통제변수'!$C$23-'00_통제변수'!$C$22)*MIN(1,MAX(0,(A9-'00_통제변수'!$C$24+1)/MAX(1,'00_통제변수'!$C$25))) -> 1.289 | J9: =H9*I9 -> 78.075116 | K9: =IF(A9>='00_통제변수'!$C$28,'00_통제변수'!$C$27,'00_통제변수'!$C$26) -> 31846 | L9: =J9*K9/10000 -> 248.63801 | M9: =L9/(1-'00_통제변수'!$B$8)*'00_통제변수'!$B$11 -> 265.07251 | N9: =E9*('00_통제변수'!$B$9+('00_통제변수'!$B$10-'00_통제변수'!$B$9)*(A9-1)/MAX(1,'00_통제변수'!$B$6-1)) -> 1199.3959
A10: 7 | B10: 2027 | C10: 7 | D10: ='00_통제변수'!$C$16*(1+'00_통제변수'!$C$17)^(A10-1) -> 11.64447 | E10: =E9+D10 -> 488.75045 | F10: ='00_통제변수'!$C$18+('00_통제변수'!$C$19-'00_통제변수'!$C$18)*MIN(1,MAX(0,(A10-'00_통제변수'!$C$20+1)/MAX(1,'00_통제변수'!$C$21))) -> 0.105 | G10: =E9*F10 -> 50.096128 | H10: =D10+G10 -> 61.740598 | I10: ='00_통제변수'!$C$22+('00_통제변수'!$C$23-'00_통제변수'!$C$22)*MIN(1,MAX(0,(A10-'00_통제변수'!$C$24+1)/MAX(1,'00_통제변수'!$C$25))) -> 1.289 | J10: =H10*I10 -> 79.583631 | K10: =IF(A10>='00_통제변수'!$C$28,'00_통제변수'!$C$27,'00_통제변수'!$C$26) -> 31846 | L10: =J10*K10/10000 -> 253.44203 | M10: =L10/(1-'00_통제변수'!$B$8)*'00_통제변수'!$B$11 -> 270.19406 | N10: =E10*('00_통제변수'!$B$9+('00_통제변수'!$B$10-'00_통제변수'!$B$9)*(A10-1)/MAX(1,'00_통제변수'!$B$6-1)) -> 1222.2075
A11: 8 | B11: 2027 | C11: 8 | D11: ='00_통제변수'!$C$16*(1+'00_통제변수'!$C$17)^(A11-1) -> 11.586248 | E11: =E10+D11 -> 500.3367 | F11: ='00_통제변수'!$C$18+('00_통제변수'!$C$19-'00_통제변수'!$C$18)*MIN(1,MAX(0,(A11-'00_통제변수'!$C$20+1)/MAX(1,'00_통제변수'!$C$21))) -> 0.105 | G11: =E10*F11 -> 51.318797 | H11: =D11+G11 -> 62.905045 | I11: ='00_통제변수'!$C$22+('00_통제변수'!$C$23-'00_통제변수'!$C$22)*MIN(1,MAX(0,(A11-'00_통제변수'!$C$24+1)/MAX(1,'00_통제변수'!$C$25))) -> 1.289 | J11: =H11*I11 -> 81.084603 | K11: =IF(A11>='00_통제변수'!$C$28,'00_통제변수'!$C$27,'00_통제변수'!$C$26) -> 31846 | L11: =J11*K11/10000 -> 258.22203 | M11: =L11/(1-'00_통제변수'!$B$8)*'00_통제변수'!$B$11 -> 275.29001 | N11: =E11*('00_통제변수'!$B$9+('00_통제변수'!$B$10-'00_통제변수'!$B$9)*(A11-1)/MAX(1,'00_통제변수'!$B$6-1)) -> 1244.5663
A12: 9 | B12: 2027 | C12: 9 | D12: ='00_통제변수'!$C$16*(1+'00_통제변수'!$C$17)^(A12-1) -> 11.528317 | E12: =E11+D12 -> 511.86501 | F12: ='00_통제변수'!$C$18+('00_통제변수'!$C$19-'00_통제변수'!$C$18)*MIN(1,MAX(0,(A12-'00_통제변수'!$C$20+1)/MAX(1,'00_통제변수'!$C$21))) -> 0.105 | G12: =E11*F12 -> 52.535353 | H12: =D12+G12 -> 64.06367 | I12: ='00_통제변수'!$C$22+('00_통제변수'!$C$23-'00_통제변수'!$C$22)*MIN(1,MAX(0,(A12-'00_통제변수'!$C$24+1)/MAX(1,'00_통제변수'!$C$25))) -> 1.289 | J12: =H12*I12 -> 82.57807 | K12: =IF(A12>='00_통제변수'!$C$28,'00_통제변수'!$C$27,'00_통제변수'!$C$26) -> 31846 | L12: =J12*K12/10000 -> 262.97812 | M12: =L12/(1-'00_통제변수'!$B$8)*'00_통제변수'!$B$11 -> 280.36047 | N12: =E12*('00_통제변수'!$B$9+('00_통제변수'!$B$10-'00_통제변수'!$B$9)*(A12-1)/MAX(1,'00_통제변수'!$B$6-1)) -> 1266.4755
A13: 10 | B13: 2027 | C13: 10 | D13: ='00_통제변수'!$C$16*(1+'00_통제변수'!$C$17)^(A13-1) -> 11.470675 | E13: =E12+D13 -> 523.33569 | F13: ='00_통제변수'!$C$18+('00_통제변수'!$C$19-'00_통제변수'!$C$18)*MIN(1,MAX(0,(A13-'00_통제변수'!$C$20+1)/MAX(1,'00_통제변수'!$C$21))) -> 0.105 | G13: =E12*F13 -> 53.745826 | H13: =D13+G13 -> 65.216501 | I13: ='00_통제변수'!$C$22+('00_통제변수'!$C$23-'00_통제변수'!$C$22)*MIN(1,MAX(0,(A13-'00_통제변수'!$C$24+1)/MAX(1,'00_통제변수'!$C$25))) -> 1.289 | J13: =H13*I13 -> 84.06407 | K13: =IF(A13>='00_통제변수'!$C$28,'00_통제변수'!$C$27,'00_통제변수'!$C$26) -> 31846 | L13: =J13*K13/10000 -> 267.71044 | M13: =L13/(1-'00_통제변수'!$B$8)*'00_통제변수'!$B$11 -> 285.40558 | N13: =E13*('00_통제변수'!$B$9+('00_통제변수'!$B$10-'00_통제변수'!$B$9)*(A13-1)/MAX(1,'00_통제변수'!$B$6-1)) -> 1287.938
A14: 11 | B14: 2027 | C14: 11 | D14: ='00_통제변수'!$C$16*(1+'00_통제변수'!$C$17)^(A14-1) -> 11.413322 | E14: =E13+D14 -> 534.74901 | F14: ='00_통제변수'!$C$18+('00_통제변수'!$C$19-'00_통제변수'!$C$18)*MIN(1,MAX(0,(A14-'00_통제변수'!$C$20+1)/MAX(1,'00_통제변수'!$C$21))) -> 0.105 | G14: =E13*F14 -> 54.950247 | H14: =D14+G14 -> 66.363569 | I14: ='00_통제변수'!$C$22+('00_통제변수'!$C$23-'00_통제변수'!$C$22)*MIN(1,MAX(0,(A14-'00_통제변수'!$C$24+1)/MAX(1,'00_통제변수'!$C$25))) -> 1.289 | J14: =H14*I14 -> 85.54264 | K14: =IF(A14>='00_통제변수'!$C$28,'00_통제변수'!$C$27,'00_통제변수'!$C$26) -> 31846 | L14: =J14*K14/10000 -> 272.41909 | M14: =L14/(1-'00_통제변수'!$B$8)*'00_통제변수'!$B$11 -> 290.42547 | N14: =E14*('00_통제변수'!$B$9+('00_통제변수'!$B$10-'00_통제변수'!$B$9)*(A14-1)/MAX(1,'00_통제변수'!$B$6-1)) -> 1308.9568
A15: 12 | B15: 2027 | C15: 12 | D15: ='00_통제변수'!$C$16*(1+'00_통제변수'!$C$17)^(A15-1) -> 11.356255 | E15: =E14+D15 -> 546.10526 | F15: ='00_통제변수'!$C$18+('00_통제변수'!$C$19-'00_통제변수'!$C$18)*MIN(1,MAX(0,(A15-'00_통제변수'!$C$20+1)/MAX(1,'00_통제변수'!$C$21))) -> 0.105 | G15: =E14*F15 -> 56.148646 | H15: =D15+G15 -> 67.504901 | I15: ='00_통제변수'!$C$22+('00_통제변수'!$C$23-'00_통제변수'!$C$22)*MIN(1,MAX(0,(A15-'00_통제변수'!$C$24+1)/MAX(1,'00_통제변수'!$C$25))) -> 1.289 | J15: =H15*I15 -> 87.013817 | K15: =IF(A15>='00_통제변수'!$C$28,'00_통제변수'!$C$27,'00_통제변수'!$C$26) -> 31846 | L15: =J15*K15/10000 -> 277.1042 | M15: =L15/(1-'00_통제변수'!$B$8)*'00_통제변수'!$B$11 -> 295.42026 | N15: =E15*('00_통제변수'!$B$9+('00_통제변수'!$B$10-'00_통제변수'!$B$9)*(A15-1)/MAX(1,'00_통제변수'!$B$6-1)) -> 1329.5349
A16: 13 | B16: 2028 | C16: 1 | D16: ='00_통제변수'!$C$16*(1+'00_통제변수'!$C$17)^(A16-1) -> 11.299474 | E16: =E15+D16 -> 557.40474 | F16: ='00_통제변수'!$C$18+('00_통제변수'!$C$19-'00_통제변수'!$C$18)*MIN(1,MAX(0,(A16-'00_통제변수'!$C$20+1)/MAX(1,'00_통제변수'!$C$21))) -> 0.105 | G16: =E15*F16 -> 57.341053 | H16: =D16+G16 -> 68.640526 | I16: ='00_통제변수'!$C$22+('00_통제변수'!$C$23-'00_통제변수'!$C$22)*MIN(1,MAX(0,(A16-'00_통제변수'!$C$24+1)/MAX(1,'00_통제변수'!$C$25))) -> 1.289 | J16: =H16*I16 -> 88.477638 | K16: =IF(A16>='00_통제변수'!$C$28,'00_통제변수'!$C$27,'00_통제변수'!$C$26) -> 31846 | L16: =J16*K16/10000 -> 281.76589 | M16: =L16/(1-'00_통제변수'!$B$8)*'00_통제변수'!$B$11 -> 300.39007 | N16: =E16*('00_통제변수'!$B$9+('00_통제변수'!$B$10-'00_통제변수'!$B$9)*(A16-1)/MAX(1,'00_통제변수'!$B$6-1)) -> 1349.6753
... A63: 60 | B63: 2031 | C63: 12 | D63: ='00_통제변수'!$C$16*(1+'00_통제변수'!$C$17)^(A63-1) -> 8.9277703 | E63: =E62+D63 -> 1029.3737 | F63: ='00_통제변수'!$C$18+('00_통제변수'!$C$19-'00_통제변수'!$C$18)*MIN(1,MAX(0,(A63-'00_통제변수'!$C$20+1)/MAX(1,'00_통제변수'!$C$21))) -> 0.105 | G63: =E62*F63 -> 107.14682 | H63: =D63+G63 -> 116.07459 | I63: ='00_통제변수'!$C$22+('00_통제변수'!$C$23-'00_통제변수'!$C$22)*MIN(1,MAX(0,(A63-'00_통제변수'!$C$24+1)/MAX(1,'00_통제변수'!$C$25))) -> 1.289 | J63: =H63*I63 -> 149.62015 | K63: =IF(A63>='00_통제변수'!$C$28,'00_통제변수'!$C$27,'00_통제변수'!$C$26) -> 31846 | L63: =J63*K63/10000 -> 476.48033 | M63: =L63/(1-'00_통제변수'!$B$8)*'00_통제변수'!$B$11 -> 507.97477 | N63: =E63*('00_통제변수'!$B$9+('00_통제변수'!$B$10-'00_통제변수'!$B$9)*(A63-1)/MAX(1,'00_통제변수'!$B$6-1)) -> 1852.8727

Sheet 02_무배+익일
A1: ② 물류혁신 (무배 인하 + 완전 익일배송)
A2: 모든 값은 00_통제변수 시트에서 결정됩니다. 이 시트는 수정하지 마십시오.
A3: 월차 | B3: 연도 | C3: 월 | D3: 신규 구매고객 (만명) | E3: 누적 구매고객 (만명) | F3: 잔존율 | G3: 기존 활동 (만명) | H3: 활동 구매고객 (만명) | I3: 구매빈도 (건/월) | J3: 구매건수 (만건) | K3: 객단가 (원) | L3: 택배매출 (억원) | M3: 총매출 (억원) | N3: 회원수 (만명)
A4: 1 | B4: 2027 | C4: 1 | D4: ='00_통제변수'!$D$16*(1+'00_통제변수'!$D$17)^(A4-1) -> 12 | E4: ='00_통제변수'!$B$7+D4 -> 418 | F4: ='00_통제변수'!$D$18+('00_통제변수'!$D$19-'00_통제변수'!$D$18)*MIN(1,MAX(0,(A4-'00_통제변수'!$D$20+1)/MAX(1,'00_통제변수'!$D$21))) -> 0.111 | G4: ='00_통제변수'!$B$7*F4 -> 45.066 | H4: =D4+G4 -> 57.066 | I4: ='00_통제변수'!$D$22+('00_통제변수'!$D$23-'00_통제변수'!$D$22)*MIN(1,MAX(0,(A4-'00_통제변수'!$D$24+1)/MAX(1,'00_통제변수'!$D$25))) -> 1.289 | J4: =H4*I4 -> 73.558074 | K4: =IF(A4>='00_통제변수'!$D$28,'00_통제변수'!$D$27,'00_통제변수'!$D$26) -> 31846 | L4: =J4*K4/10000 -> 234.25304 | M4: =L4/(1-'00_통제변수'!$B$8)*'00_통제변수'!$B$11 -> 249.73672 | N4: =E4*('00_통제변수'!$B$9+('00_통제변수'!$B$10-'00_통제변수'!$B$9)*(A4-1)/MAX(1,'00_통제변수'!$B$6-1)) -> 1078.44
A5: 2 | B5: 2027 | C5: 2 | D5: ='00_통제변수'!$D$16*(1+'00_통제변수'!$D$17)^(A5-1) -> 11.988 | E5: =E4+D5 -> 429.988 | F5: ='00_통제변수'!$D$18+('00_통제변수'!$D$19-'00_통제변수'!$D$18)*MIN(1,MAX(0,(A5-'00_통제변수'!$D$20+1)/MAX(1,'00_통제변수'!$D$21))) -> 0.111 | G5: =E4*F5 -> 46.398 | H5: =D5+G5 -> 58.386 | I5: ='00_통제변수'!$D$22+('00_통제변수'!$D$23-'00_통제변수'!$D$22)*MIN(1,MAX(0,(A5-'00_통제변수'!$D$24+1)/MAX(1,'00_통제변수'!$D$25))) -> 1.289 | J5: =H5*I5 -> 75.259554 | K5: =IF(A5>='00_통제변수'!$D$28,'00_통제변수'!$D$27,'00_통제변수'!$D$26) -> 31846 | L5: =J5*K5/10000 -> 239.67158 | M5: =L5/(1-'00_통제변수'!$B$8)*'00_통제변수'!$B$11 -> 255.51341 | N5: =E5*('00_통제변수'!$B$9+('00_통제변수'!$B$10-'00_통제변수'!$B$9)*(A5-1)/MAX(1,'00_통제변수'!$B$6-1)) -> 1103.6845
A6: 3 | B6: 2027 | C6: 3 | D6: ='00_통제변수'!$D$16*(1+'00_통제변수'!$D$17)^(A6-1) -> 11.976012 | E6: =E5+D6 -> 441.96401 | F6: ='00_통제변수'!$D$18+('00_통제변수'!$D$19-'00_통제변수'!$D$18)*MIN(1,MAX(0,(A6-'00_통제변수'!$D$20+1)/MAX(1,'00_통제변수'!$D$21))) -> 0.111 | G6: =E5*F6 -> 47.728668 | H6: =D6+G6 -> 59.70468 | I6: ='00_통제변수'!$D$22+('00_통제변수'!$D$23-'00_통제변수'!$D$22)*MIN(1,MAX(0,(A6-'00_통제변수'!$D$24+1)/MAX(1,'00_통제변수'!$D$25))) -> 1.289 | J6: =H6*I6 -> 76.959333 | K6: =IF(A6>='00_통제변수'!$D$28,'00_통제변수'!$D$27,'00_통제변수'!$D$26) -> 31846 | L6: =J6*K6/10000 -> 245.08469 | M6: =L6/(1-'00_통제변수'!$B$8)*'00_통제변수'!$B$11 -> 261.28432 | N6: =E6*('00_통제변수'!$B$9+('00_통제변수'!$B$10-'00_통제변수'!$B$9)*(A6-1)/MAX(1,'00_통제변수'!$B$6-1)) -> 1128.5813
A7: 4 | B7: 2027 | C7: 4 | D7: ='00_통제변수'!$D$16*(1+'00_통제변수'!$D$17)^(A7-1) -> 11.964036 | E7: =E6+D7 -> 453.92805 | F7: ='00_통제변수'!$D$18+('00_통제변수'!$D$19-'00_통제변수'!$D$18)*MIN(1,MAX(0,(A7-'00_통제변수'!$D$20+1)/MAX(1,'00_통제변수'!$D$21))) -> 0.111 | G7: =E6*F7 -> 49.058005 | H7: =D7+G7 -> 61.022041 | I7: ='00_통제변수'!$D$22+('00_통제변수'!$D$23-'00_통제변수'!$D$22)*MIN(1,MAX(0,(A7-'00_통제변수'!$D$24+1)/MAX(1,'00_통제변수'!$D$25))) -> 1.289 | J7: =H7*I7 -> 78.657411 | K7: =IF(A7>='00_통제변수'!$D$28,'00_통제변수'!$D$27,'00_통제변수'!$D$26) -> 31846 | L7: =J7*K7/10000 -> 250.49239 | M7: =L7/(1-'00_통제변수'!$B$8)*'00_통제변수'!$B$11 -> 267.04946 | N7: =E7*('00_통제변수'!$B$9+('00_통제변수'!$B$10-'00_통제변수'!$B$9)*(A7-1)/MAX(1,'00_통제변수'!$B$6-1)) -> 1153.1311
A8: 5 | B8: 2027 | C8: 5 | D8: ='00_통제변수'!$D$16*(1+'00_통제변수'!$D$17)^(A8-1) -> 11.952072 | E8: =E7+D8 -> 465.88012 | F8: ='00_통제변수'!$D$18+('00_통제변수'!$D$19-'00_통제변수'!$D$18)*MIN(1,MAX(0,(A8-'00_통제변수'!$D$20+1)/MAX(1,'00_통제변수'!$D$21))) -> 0.111 | G8: =E7*F8 -> 50.386013 | H8: =D8+G8 -> 62.338085 | I8: ='00_통제변수'!$D$22+('00_통제변수'!$D$23-'00_통제변수'!$D$22)*MIN(1,MAX(0,(A8-'00_통제변수'!$D$24+1)/MAX(1,'00_통제변수'!$D$25))) -> 1.289 | J8: =H8*I8 -> 80.353792 | K8: =IF(A8>='00_통제변수'!$D$28,'00_통제변수'!$D$27,'00_통제변수'!$D$26) -> 31846 | L8: =J8*K8/10000 -> 255.89469 | M8: =L8/(1-'00_통제변수'!$B$8)*'00_통제변수'!$B$11 -> 272.80883 | N8: =E8*('00_통제변수'!$B$9+('00_통제변수'!$B$10-'00_통제변수'!$B$9)*(A8-1)/MAX(1,'00_통제변수'!$B$6-1)) -> 1177.3343
A9: 6 | B9: 2027 | C9: 6 | D9: ='00_통제변수'!$D$16*(1+'00_통제변수'!$D$17)^(A9-1) -> 11.94012 | E9: =E8+D9 -> 477.82024 | F9: ='00_통제변수'!$D$18+('00_통제변수'!$D$19-'00_통제변수'!$D$18)*MIN(1,MAX(0,(A9-'00_통제변수'!$D$20+1)/MAX(1,'00_통제변수'!$D$21))) -> 0.11192857 | G9: =E8*F9 -> 52.145296 | H9: =D9+G9 -> 64.085416 | I9: ='00_통제변수'!$D$22+('00_통제변수'!$D$23-'00_통제변수'!$D$22)*MIN(1,MAX(0,(A9-'00_통제변수'!$D$24+1)/MAX(1,'00_통제변수'!$D$25))) -> 1.3060333 | J9: =H9*I9 -> 83.69769 | K9: =IF(A9>='00_통제변수'!$D$28,'00_통제변수'!$D$27,'00_통제변수'!$D$26) -> 26000 | L9: =J9*K9/10000 -> 217.61399 | M9: =L9/(1-'00_통제변수'!$B$8)*'00_통제변수'!$B$11 -> 231.99786 | N9: =E9*('00_통제변수'!$B$9+('00_통제변수'!$B$10-'00_통제변수'!$B$9)*(A9-1)/MAX(1,'00_통제변수'!$B$6-1)) -> 1201.1915
A10: 7 | B10: 2027 | C10: 7 | D10: ='00_통제변수'!$D$16*(1+'00_통제변수'!$D$17)^(A10-1) -> 11.92818 | E10: =E9+D10 -> 489.74842 | F10: ='00_통제변수'!$D$18+('00_통제변수'!$D$19-'00_통제변수'!$D$18)*MIN(1,MAX(0,(A10-'00_통제변수'!$D$20+1)/MAX(1,'00_통제변수'!$D$21))) -> 0.11285714 | G10: =E9*F10 -> 53.925427 | H10: =D10+G10 -> 65.853607 | I10: ='00_통제변수'!$D$22+('00_통제변수'!$D$23-'00_통제변수'!$D$22)*MIN(1,MAX(0,(A10-'00_통제변수'!$D$24+1)/MAX(1,'00_통제변수'!$D$25))) -> 1.3230667 | J10: =H10*I10 -> 87.128712 | K10: =IF(A10>='00_통제변수'!$D$28,'00_통제변수'!$D$27,'00_통제변수'!$D$26) -> 26000 | L10: =J10*K10/10000 -> 226.53465 | M10: =L10/(1-'00_통제변수'!$B$8)*'00_통제변수'!$B$11 -> 241.50816 | N10: =E10*('00_통제변수'!$B$9+('00_통제변수'!$B$10-'00_통제변수'!$B$9)*(A10-1)/MAX(1,'00_통제변수'!$B$6-1)) -> 1224.7031
A11: 8 | B11: 2027 | C11: 8 | D11: ='00_통제변수'!$D$16*(1+'00_통제변수'!$D$17)^(A11-1) -> 11.916252 | E11: =E10+D11 -> 501.66467 | F11: ='00_통제변수'!$D$18+('00_통제변수'!$D$19-'00_통제변수'!$D$18)*MIN(1,MAX(0,(A11-'00_통제변수'!$D$20+1)/MAX(1,'00_통제변수'!$D$21))) -> 0.11378571 | G11: =E10*F11 -> 55.726374 | H11: =D11+G11 -> 67.642625 | I11: ='00_통제변수'!$D$22+('00_통제변수'!$D$23-'00_통제변수'!$D$22)*MIN(1,MAX(0,(A11-'00_통제변수'!$D$24+1)/MAX(1,'00_통제변수'!$D$25))) -> 1.3401 | J11: =H11*I11 -> 90.647882 | K11: =IF(A11>='00_통제변수'!$D$28,'00_통제변수'!$D$27,'00_통제변수'!$D$26) -> 26000 | L11: =J11*K11/10000 -> 235.68449 | M11: =L11/(1-'00_통제변수'!$B$8)*'00_통제변수'!$B$11 -> 251.26279 | N11: =E11*('00_통제변수'!$B$9+('00_통제변수'!$B$10-'00_통제변수'!$B$9)*(A11-1)/MAX(1,'00_통제변수'!$B$6-1)) -> 1247.8696
A12: 9 | B12: 2027 | C12: 9 | D12: ='00_통제변수'!$D$16*(1+'00_통제변수'!$D$17)^(A12-1) -> 11.904335 | E12: =E11+D12 -> 513.56901 | F12: ='00_통제변수'!$D$18+('00_통제변수'!$D$19-'00_통제변수'!$D$18)*MIN(1,MAX(0,(A12-'00_통제변수'!$D$20+1)/MAX(1,'00_통제변수'!$D$21))) -> 0.11471429 | G12: =E11*F12 -> 57.548104 | H12: =D12+G12 -> 69.45244 | I12: ='00_통제변수'!$D$22+('00_통제변수'!$D$23-'00_통제변수'!$D$22)*MIN(1,MAX(0,(A12-'00_통제변수'!$D$24+1)/MAX(1,'00_통제변수'!$D$25))) -> 1.3571333 | J12: =H12*I12 -> 94.256221 | K12: =IF(A12>='00_통제변수'!$D$28,'00_통제변수'!$D$27,'00_통제변수'!$D$26) -> 26000 | L12: =J12*K12/10000 -> 245.06617 | M12: =L12/(1-'00_통제변수'!$B$8)*'00_통제변수'!$B$11 -> 261.26458 | N12: =E12*('00_통제변수'!$B$9+('00_통제변수'!$B$10-'00_통제변수'!$B$9)*(A12-1)/MAX(1,'00_통제변수'!$B$6-1)) -> 1270.6916
A13: 10 | B13: 2027 | C13: 10 | D13: ='00_통제변수'!$D$16*(1+'00_통제변수'!$D$17)^(A13-1) -> 11.892431 | E13: =E12+D13 -> 525.46144 | F13: ='00_통제변수'!$D$18+('00_통제변수'!$D$19-'00_통제변수'!$D$18)*MIN(1,MAX(0,(A13-'00_통제변수'!$D$20+1)/MAX(1,'00_통제변수'!$D$21))) -> 0.11564286 | G13: =E12*F13 -> 59.390587 | H13: =D13+G13 -> 71.283018 | I13: ='00_통제변수'!$D$22+('00_통제변수'!$D$23-'00_통제변수'!$D$22)*MIN(1,MAX(0,(A13-'00_통제변수'!$D$24+1)/MAX(1,'00_통제변수'!$D$25))) -> 1.3741667 | J13: =H13*I13 -> 97.954748 | K13: =IF(A13>='00_통제변수'!$D$28,'00_통제변수'!$D$27,'00_통제변수'!$D$26) -> 26000 | L13: =J13*K13/10000 -> 254.68234 | M13: =L13/(1-'00_통제변수'!$B$8)*'00_통제변수'!$B$11 -> 271.51636 | N13: =E13*('00_통제변수'!$B$9+('00_통제변수'!$B$10-'00_통제변수'!$B$9)*(A13-1)/MAX(1,'00_통제변수'!$B$6-1)) -> 1293.1695
A14: 11 | B14: 2027 | C14: 11 | D14: ='00_통제변수'!$D$16*(1+'00_통제변수'!$D$17)^(A14-1) -> 11.880539 | E14: =E13+D14 -> 537.34198 | F14: ='00_통제변수'!$D$18+('00_통제변수'!$D$19-'00_통제변수'!$D$18)*MIN(1,MAX(0,(A14-'00_통제변수'!$D$20+1)/MAX(1,'00_통제변수'!$D$21))) -> 0.11657143 | G14: =E13*F14 -> 61.25379 | H14: =D14+G14 -> 73.134329 | I14: ='00_통제변수'!$D$22+('00_통제변수'!$D$23-'00_통제변수'!$D$22)*MIN(1,MAX(0,(A14-'00_통제변수'!$D$24+1)/MAX(1,'00_통제변수'!$D$25))) -> 1.3912 | J14: =H14*I14 -> 101.74448 | K14: =IF(A14>='00_통제변수'!$D$28,'00_통제변수'!$D$27,'00_통제변수'!$D$26) -> 26000 | L14: =J14*K14/10000 -> 264.53564 | M14: =L14/(1-'00_통제변수'!$B$8)*'00_통제변수'!$B$11 -> 282.02094 | N14: =E14*('00_통제변수'!$B$9+('00_통제변수'!$B$10-'00_통제변수'!$B$9)*(A14-1)/MAX(1,'00_통제변수'!$B$6-1)) -> 1315.3039
A15: 12 | B15: 2027 | C15: 12 | D15: ='00_통제변수'!$D$16*(1+'00_통제변수'!$D$17)^(A15-1) -> 11.868658 | E15: =E14+D15 -> 549.21063 | F15: ='00_통제변수'!$D$18+('00_통제변수'!$D$19-'00_통제변수'!$D$18)*MIN(1,MAX(0,(A15-'00_통제변수'!$D$20+1)/MAX(1,'00_통제변수'!$D$21))) -> 0.1175 | G15: =E14*F15 -> 63.137682 | H15: =D15+G15 -> 75.00634 | I15: ='00_통제변수'!$D$22+('00_통제변수'!$D$23-'00_통제변수'!$D$22)*MIN(1,MAX(0,(A15-'00_통제변수'!$D$24+1)/MAX(1,'00_통제변수'!$D$25))) -> 1.4082333 | J15: =H15*I15 -> 105.62643 | K15: =IF(A15>='00_통제변수'!$D$28,'00_통제변수'!$D$27,'00_통제변수'!$D$26) -> 26000 | L15: =J15*K15/10000 -> 274.62871 | M15: =L15/(1-'00_통제변수'!$B$8)*'00_통제변수'!$B$11 -> 292.78115 | N15: =E15*('00_통제변수'!$B$9+('00_통제변수'!$B$10-'00_통제변수'!$B$9)*(A15-1)/MAX(1,'00_통제변수'!$B$6-1)) -> 1337.0952
A16: 13 | B16: 2028 | C16: 1 | D16: ='00_통제변수'!$D$16*(1+'00_통제변수'!$D$17)^(A16-1) -> 11.856789 | E16: =E15+D16 -> 561.06742 | F16: ='00_통제변수'!$D$18+('00_통제변수'!$D$19-'00_통제변수'!$D$18)*MIN(1,MAX(0,(A16-'00_통제변수'!$D$20+1)/MAX(1,'00_통제변수'!$D$21))) -> 0.11842857 | G16: =E15*F16 -> 65.042231 | H16: =D16+G16 -> 76.89902 | I16: ='00_통제변수'!$D$22+('00_통제변수'!$D$23-'00_통제변수'!$D$22)*MIN(1,MAX(0,(A16-'00_통제변수'!$D$24+1)/MAX(1,'00_통제변수'!$D$25))) -> 1.4252667 | J16: =H16*I16 -> 109.60161 | K16: =IF(A16>='00_통제변수'!$D$28,'00_통제변수'!$D$27,'00_통제변수'!$D$26) -> 26000 | L16: =J16*K16/10000 -> 284.96419 | M16: =L16/(1-'00_통제변수'!$B$8)*'00_통제변수'!$B$11 -> 303.79977 | N16: =E16*('00_통제변수'!$B$9+('00_통제변수'!$B$10-'00_통제변수'!$B$9)*(A16-1)/MAX(1,'00_통제변수'!$B$6-1)) -> 1358.5439
... A63: 60 | B63: 2031 | C63: 12 | D63: ='00_통제변수'!$D$16*(1+'00_통제변수'!$D$17)^(A63-1) -> 11.312147 | E63: =E62+D63 -> 1105.1649 | F63: ='00_통제변수'!$D$18+('00_통제변수'!$D$19-'00_통제변수'!$D$18)*MIN(1,MAX(0,(A63-'00_통제변수'!$D$20+1)/MAX(1,'00_통제변수'!$D$21))) -> 0.15 | G63: =E62*F63 -> 164.07791 | H63: =D63+G63 -> 175.39005 | I63: ='00_통제변수'!$D$22+('00_통제변수'!$D$23-'00_통제변수'!$D$22)*MIN(1,MAX(0,(A63-'00_통제변수'!$D$24+1)/MAX(1,'00_통제변수'!$D$25))) -> 1.8 | J63: =H63*I63 -> 315.7021 | K63: =IF(A63>='00_통제변수'!$D$28,'00_통제변수'!$D$27,'00_통제변수'!$D$26) -> 26000 | L63: =J63*K63/10000 -> 820.82545 | M63: =L63/(1-'00_통제변수'!$B$8)*'00_통제변수'!$B$11 -> 875.08044 | N63: =E63*('00_통제변수'!$B$9+('00_통제변수'!$B$10-'00_통제변수'!$B$9)*(A63-1)/MAX(1,'00_통제변수'!$B$6-1)) -> 1989.2967

Sheet 03_익일배송
A1: ③ 물류혁신 (완전 익일배송)
A2: 모든 값은 00_통제변수 시트에서 결정됩니다. 이 시트는 수정하지 마십시오.
A3: 월차 | B3: 연도 | C3: 월 | D3: 신규 구매고객 (만명) | E3: 누적 구매고객 (만명) | F3: 잔존율 | G3: 기존 활동 (만명) | H3: 활동 구매고객 (만명) | I3: 구매빈도 (건/월) | J3: 구매건수 (만건) | K3: 객단가 (원) | L3: 택배매출 (억원) | M3: 총매출 (억원) | N3: 회원수 (만명)
A4: 1 | B4: 2027 | C4: 1 | D4: ='00_통제변수'!$E$16*(1+'00_통제변수'!$E$17)^(A4-1) -> 12 | E4: ='00_통제변수'!$B$7+D4 -> 418 | F4: ='00_통제변수'!$E$18+('00_통제변수'!$E$19-'00_통제변수'!$E$18)*MIN(1,MAX(0,(A4-'00_통제변수'!$E$20+1)/MAX(1,'00_통제변수'!$E$21))) -> 0.111 | G4: ='00_통제변수'!$B$7*F4 -> 45.066 | H4: =D4+G4 -> 57.066 | I4: ='00_통제변수'!$E$22+('00_통제변수'!$E$23-'00_통제변수'!$E$22)*MIN(1,MAX(0,(A4-'00_통제변수'!$E$24+1)/MAX(1,'00_통제변수'!$E$25))) -> 1.289 | J4: =H4*I4 -> 73.558074 | K4: =IF(A4>='00_통제변수'!$E$28,'00_통제변수'!$E$27,'00_통제변수'!$E$26) -> 31846 | L4: =J4*K4/10000 -> 234.25304 | M4: =L4/(1-'00_통제변수'!$B$8)*'00_통제변수'!$B$11 -> 249.73672 | N4: =E4*('00_통제변수'!$B$9+('00_통제변수'!$B$10-'00_통제변수'!$B$9)*(A4-1)/MAX(1,'00_통제변수'!$B$6-1)) -> 1078.44
A5: 2 | B5: 2027 | C5: 2 | D5: ='00_통제변수'!$E$16*(1+'00_통제변수'!$E$17)^(A5-1) -> 11.964 | E5: =E4+D5 -> 429.964 | F5: ='00_통제변수'!$E$18+('00_통제변수'!$E$19-'00_통제변수'!$E$18)*MIN(1,MAX(0,(A5-'00_통제변수'!$E$20+1)/MAX(1,'00_통제변수'!$E$21))) -> 0.111 | G5: =E4*F5 -> 46.398 | H5: =D5+G5 -> 58.362 | I5: ='00_통제변수'!$E$22+('00_통제변수'!$E$23-'00_통제변수'!$E$22)*MIN(1,MAX(0,(A5-'00_통제변수'!$E$24+1)/MAX(1,'00_통제변수'!$E$25))) -> 1.289 | J5: =H5*I5 -> 75.228618 | K5: =IF(A5>='00_통제변수'!$E$28,'00_통제변수'!$E$27,'00_통제변수'!$E$26) -> 31846 | L5: =J5*K5/10000 -> 239.57306 | M5: =L5/(1-'00_통제변수'!$B$8)*'00_통제변수'!$B$11 -> 255.40838 | N5: =E5*('00_통제변수'!$B$9+('00_통제변수'!$B$10-'00_통제변수'!$B$9)*(A5-1)/MAX(1,'00_통제변수'!$B$6-1)) -> 1103.6229
A6: 3 | B6: 2027 | C6: 3 | D6: ='00_통제변수'!$E$16*(1+'00_통제변수'!$E$17)^(A6-1) -> 11.928108 | E6: =E5+D6 -> 441.89211 | F6: ='00_통제변수'!$E$18+('00_통제변수'!$E$19-'00_통제변수'!$E$18)*MIN(1,MAX(0,(A6-'00_통제변수'!$E$20+1)/MAX(1,'00_통제변수'!$E$21))) -> 0.111 | G6: =E5*F6 -> 47.726004 | H6: =D6+G6 -> 59.654112 | I6: ='00_통제변수'!$E$22+('00_통제변수'!$E$23-'00_통제변수'!$E$22)*MIN(1,MAX(0,(A6-'00_통제변수'!$E$24+1)/MAX(1,'00_통제변수'!$E$25))) -> 1.289 | J6: =H6*I6 -> 76.89415 | K6: =IF(A6>='00_통제변수'!$E$28,'00_통제변수'!$E$27,'00_통제변수'!$E$26) -> 31846 | L6: =J6*K6/10000 -> 244.87711 | M6: =L6/(1-'00_통제변수'!$B$8)*'00_통제변수'!$B$11 -> 261.06302 | N6: =E6*('00_통제변수'!$B$9+('00_통제변수'!$B$10-'00_통제변수'!$B$9)*(A6-1)/MAX(1,'00_통제변수'!$B$6-1)) -> 1128.3977
A7: 4 | B7: 2027 | C7: 4 | D7: ='00_통제변수'!$E$16*(1+'00_통제변수'!$E$17)^(A7-1) -> 11.892324 | E7: =E6+D7 -> 453.78443 | F7: ='00_통제변수'!$E$18+('00_통제변수'!$E$19-'00_통제변수'!$E$18)*MIN(1,MAX(0,(A7-'00_통제변수'!$E$20+1)/MAX(1,'00_통제변수'!$E$21))) -> 0.111 | G7: =E6*F7 -> 49.050024 | H7: =D7+G7 -> 60.942348 | I7: ='00_통제변수'!$E$22+('00_통제변수'!$E$23-'00_통제변수'!$E$22)*MIN(1,MAX(0,(A7-'00_통제변수'!$E$24+1)/MAX(1,'00_통제변수'!$E$25))) -> 1.289 | J7: =H7*I7 -> 78.554686 | K7: =IF(A7>='00_통제변수'!$E$28,'00_통제변수'!$E$27,'00_통제변수'!$E$26) -> 31846 | L7: =J7*K7/10000 -> 250.16525 | M7: =L7/(1-'00_통제변수'!$B$8)*'00_통제변수'!$B$11 -> 266.7007 | N7: =E7*('00_통제변수'!$B$9+('00_통제변수'!$B$10-'00_통제변수'!$B$9)*(A7-1)/MAX(1,'00_통제변수'!$B$6-1)) -> 1152.7663
A8: 5 | B8: 2027 | C8: 5 | D8: ='00_통제변수'!$E$16*(1+'00_통제변수'!$E$17)^(A8-1) -> 11.856647 | E8: =E7+D8 -> 465.64108 | F8: ='00_통제변수'!$E$18+('00_통제변수'!$E$19-'00_통제변수'!$E$18)*MIN(1,MAX(0,(A8-'00_통제변수'!$E$20+1)/MAX(1,'00_통제변수'!$E$21))) -> 0.111 | G8: =E7*F8 -> 50.370072 | H8: =D8+G8 -> 62.226719 | I8: ='00_통제변수'!$E$22+('00_통제변수'!$E$23-'00_통제변수'!$E$22)*MIN(1,MAX(0,(A8-'00_통제변수'!$E$24+1)/MAX(1,'00_통제변수'!$E$25))) -> 1.289 | J8: =H8*I8 -> 80.21024 | K8: =IF(A8>='00_통제변수'!$E$28,'00_통제변수'!$E$27,'00_통제변수'!$E$26) -> 31846 | L8: =J8*K8/10000 -> 255.43753 | M8: =L8/(1-'00_통제변수'!$B$8)*'00_통제변수'!$B$11 -> 272.32146 | N8: =E8*('00_통제변수'!$B$9+('00_통제변수'!$B$10-'00_통제변수'!$B$9)*(A8-1)/MAX(1,'00_통제변수'!$B$6-1)) -> 1176.7303
A9: 6 | B9: 2027 | C9: 6 | D9: ='00_통제변수'!$E$16*(1+'00_통제변수'!$E$17)^(A9-1) -> 11.821077 | E9: =E8+D9 -> 477.46216 | F9: ='00_통제변수'!$E$18+('00_통제변수'!$E$19-'00_통제변수'!$E$18)*MIN(1,MAX(0,(A9-'00_통제변수'!$E$20+1)/MAX(1,'00_통제변수'!$E$21))) -> 0.1111875 | G9: =E8*F9 -> 51.773467 | H9: =D9+G9 -> 63.594544 | I9: ='00_통제변수'!$E$22+('00_통제변수'!$E$23-'00_통제변수'!$E$22)*MIN(1,MAX(0,(A9-'00_통제변수'!$E$24+1)/MAX(1,'00_통제변수'!$E$25))) -> 1.2944375 | J9: =H9*I9 -> 82.319163 | K9: =IF(A9>='00_통제변수'!$E$28,'00_통제변수'!$E$27,'00_통제변수'!$E$26) -> 31846 | L9: =J9*K9/10000 -> 262.15361 | M9: =L9/(1-'00_통제변수'!$B$8)*'00_통제변수'!$B$11 -> 279.48146 | N9: =E9*('00_통제변수'!$B$9+('00_통제변수'!$B$10-'00_통제변수'!$B$9)*(A9-1)/MAX(1,'00_통제변수'!$B$6-1)) -> 1200.2913
A10: 7 | B10: 2027 | C10: 7 | D10: ='00_통제변수'!$E$16*(1+'00_통제변수'!$E$17)^(A10-1) -> 11.785614 | E10: =E9+D10 -> 489.24777 | F10: ='00_통제변수'!$E$18+('00_통제변수'!$E$19-'00_통제변수'!$E$18)*MIN(1,MAX(0,(A10-'00_통제변수'!$E$20+1)/MAX(1,'00_통제변수'!$E$21))) -> 0.111375 | G10: =E9*F10 -> 53.177348 | H10: =D10+G10 -> 64.962961 | I10: ='00_통제변수'!$E$22+('00_통제변수'!$E$23-'00_통제변수'!$E$22)*MIN(1,MAX(0,(A10-'00_통제변수'!$E$24+1)/MAX(1,'00_통제변수'!$E$25))) -> 1.299875 | J10: =H10*I10 -> 84.443729 | K10: =IF(A10>='00_통제변수'!$E$28,'00_통제변수'!$E$27,'00_통제변수'!$E$26) -> 31846 | L10: =J10*K10/10000 -> 268.9195 | M10: =L10/(1-'00_통제변수'!$B$8)*'00_통제변수'!$B$11 -> 286.69456 | N10: =E10*('00_통제변수'!$B$9+('00_통제변수'!$B$10-'00_통제변수'!$B$9)*(A10-1)/MAX(1,'00_통제변수'!$B$6-1)) -> 1223.4511
A11: 8 | B11: 2027 | C11: 8 | D11: ='00_통제변수'!$E$16*(1+'00_통제변수'!$E$17)^(A11-1) -> 11.750257 | E11: =E10+D11 -> 500.99803 | F11: ='00_통제변수'!$E$18+('00_통제변수'!$E$19-'00_통제변수'!$E$18)*MIN(1,MAX(0,(A11-'00_통제변수'!$E$20+1)/MAX(1,'00_통제변수'!$E$21))) -> 0.1115625 | G11: =E10*F11 -> 54.581704 | H11: =D11+G11 -> 66.331961 | I11: ='00_통제변수'!$E$22+('00_통제변수'!$E$23-'00_통제변수'!$E$22)*MIN(1,MAX(0,(A11-'00_통제변수'!$E$24+1)/MAX(1,'00_통제변수'!$E$25))) -> 1.3053125 | J11: =H11*I11 -> 86.583938 | K11: =IF(A11>='00_통제변수'!$E$28,'00_통제변수'!$E$27,'00_통제변수'!$E$26) -> 31846 | L11: =J11*K11/10000 -> 275.73521 | M11: =L11/(1-'00_통제변수'!$B$8)*'00_통제변수'!$B$11 -> 293.96078 | N11: =E11*('00_통제변수'!$B$9+('00_통제변수'!$B$10-'00_통제변수'!$B$9)*(A11-1)/MAX(1,'00_통제변수'!$B$6-1)) -> 1246.2114
A12: 9 | B12: 2027 | C12: 9 | D12: ='00_통제변수'!$E$16*(1+'00_통제변수'!$E$17)^(A12-1) -> 11.715006 | E12: =E11+D12 -> 512.71303 | F12: ='00_통제변수'!$E$18+('00_통제변수'!$E$19-'00_통제변수'!$E$18)*MIN(1,MAX(0,(A12-'00_통제변수'!$E$20+1)/MAX(1,'00_통제변수'!$E$21))) -> 0.11175 | G12: =E11*F12 -> 55.986529 | H12: =D12+G12 -> 67.701535 | I12: ='00_통제변수'!$E$22+('00_통제변수'!$E$23-'00_통제변수'!$E$22)*MIN(1,MAX(0,(A12-'00_통제변수'!$E$24+1)/MAX(1,'00_통제변수'!$E$25))) -> 1.31075 | J12: =H12*I12 -> 88.739787 | K12: =IF(A12>='00_통제변수'!$E$28,'00_통제변수'!$E$27,'00_통제변수'!$E$26) -> 31846 | L12: =J12*K12/10000 -> 282.60073 | M12: =L12/(1-'00_통제변수'!$B$8)*'00_통제변수'!$B$11 -> 301.28009 | N12: =E12*('00_통제변수'!$B$9+('00_통제변수'!$B$10-'00_통제변수'!$B$9)*(A12-1)/MAX(1,'00_통제변수'!$B$6-1)) -> 1268.5737
A13: 10 | B13: 2027 | C13: 10 | D13: ='00_통제변수'!$E$16*(1+'00_통제변수'!$E$17)^(A13-1) -> 11.679861 | E13: =E12+D13 -> 524.39289 | F13: ='00_통제변수'!$E$18+('00_통제변수'!$E$19-'00_통제변수'!$E$18)*MIN(1,MAX(0,(A13-'00_통제변수'!$E$20+1)/MAX(1,'00_통제변수'!$E$21))) -> 0.1119375 | G13: =E12*F13 -> 57.391815 | H13: =D13+G13 -> 69.071676 | I13: ='00_통제변수'!$E$22+('00_통제변수'!$E$23-'00_통제변수'!$E$22)*MIN(1,MAX(0,(A13-'00_통제변수'!$E$24+1)/MAX(1,'00_통제변수'!$E$25))) -> 1.3161875 | J13: =H13*I13 -> 90.911276 | K13: =IF(A13>='00_통제변수'!$E$28,'00_통제변수'!$E$27,'00_통제변수'!$E$26) -> 31846 | L13: =J13*K13/10000 -> 289.51605 | M13: =L13/(1-'00_통제변수'!$B$8)*'00_통제변수'!$B$11 -> 308.65251 | N13: =E13*('00_통제변수'!$B$9+('00_통제변수'!$B$10-'00_통제변수'!$B$9)*(A13-1)/MAX(1,'00_통제변수'!$B$6-1)) -> 1290.5398
A14: 11 | B14: 2027 | C14: 11 | D14: ='00_통제변수'!$E$16*(1+'00_통제변수'!$E$17)^(A14-1) -> 11.644821 | E14: =E13+D14 -> 536.03771 | F14: ='00_통제변수'!$E$18+('00_통제변수'!$E$19-'00_통제변수'!$E$18)*MIN(1,MAX(0,(A14-'00_통제변수'!$E$20+1)/MAX(1,'00_통제변수'!$E$21))) -> 0.112125 | G14: =E13*F14 -> 58.797553 | H14: =D14+G14 -> 70.442374 | I14: ='00_통제변수'!$E$22+('00_통제변수'!$E$23-'00_통제변수'!$E$22)*MIN(1,MAX(0,(A14-'00_통제변수'!$E$24+1)/MAX(1,'00_통제변수'!$E$25))) -> 1.321625 | J14: =H14*I14 -> 93.098403 | K14: =IF(A14>='00_통제변수'!$E$28,'00_통제변수'!$E$27,'00_통제변수'!$E$26) -> 31846 | L14: =J14*K14/10000 -> 296.48117 | M14: =L14/(1-'00_통제변수'!$B$8)*'00_통제변수'!$B$11 -> 316.07801 | N14: =E14*('00_통제변수'!$B$9+('00_통제변수'!$B$10-'00_통제변수'!$B$9)*(A14-1)/MAX(1,'00_통제변수'!$B$6-1)) -> 1312.1113
A15: 12 | B15: 2027 | C15: 12 | D15: ='00_통제변수'!$E$16*(1+'00_통제변수'!$E$17)^(A15-1) -> 11.609887 | E15: =E14+D15 -> 547.6476 | F15: ='00_통제변수'!$E$18+('00_통제변수'!$E$19-'00_통제변수'!$E$18)*MIN(1,MAX(0,(A15-'00_통제변수'!$E$20+1)/MAX(1,'00_통제변수'!$E$21))) -> 0.1123125 | G15: =E14*F15 -> 60.203736 | H15: =D15+G15 -> 71.813623 | I15: ='00_통제변수'!$E$22+('00_통제변수'!$E$23-'00_통제변수'!$E$22)*MIN(1,MAX(0,(A15-'00_통제변수'!$E$24+1)/MAX(1,'00_통제변수'!$E$25))) -> 1.3270625 | J15: =H15*I15 -> 95.301165 | K15: =IF(A15>='00_통제변수'!$E$28,'00_통제변수'!$E$27,'00_통제변수'!$E$26) -> 31846 | L15: =J15*K15/10000 -> 303.49609 | M15: =L15/(1-'00_통제변수'!$B$8)*'00_통제변수'!$B$11 -> 323.5566 | N15: =E15*('00_통제변수'!$B$9+('00_통제변수'!$B$10-'00_통제변수'!$B$9)*(A15-1)/MAX(1,'00_통제변수'!$B$6-1)) -> 1333.2899
A16: 13 | B16: 2028 | C16: 1 | D16: ='00_통제변수'!$E$16*(1+'00_통제변수'!$E$17)^(A16-1) -> 11.575057 | E16: =E15+D16 -> 559.22266 | F16: ='00_통제변수'!$E$18+('00_통제변수'!$E$19-'00_통제변수'!$E$18)*MIN(1,MAX(0,(A16-'00_통제변수'!$E$20+1)/MAX(1,'00_통제변수'!$E$21))) -> 0.1125 | G16: =E15*F16 -> 61.610355 | H16: =D16+G16 -> 73.185412 | I16: ='00_통제변수'!$E$22+('00_통제변수'!$E$23-'00_통제변수'!$E$22)*MIN(1,MAX(0,(A16-'00_통제변수'!$E$24+1)/MAX(1,'00_통제변수'!$E$25))) -> 1.3325 | J16: =H16*I16 -> 97.519562 | K16: =IF(A16>='00_통제변수'!$E$28,'00_통제변수'!$E$27,'00_통제변수'!$E$26) -> 31846 | L16: =J16*K16/10000 -> 310.5608 | M16: =L16/(1-'00_통제변수'!$B$8)*'00_통제변수'!$B$11 -> 331.08827 | N16: =E16*('00_통제변수'!$B$9+('00_통제변수'!$B$10-'00_통제변수'!$B$9)*(A16-1)/MAX(1,'00_통제변수'!$B$6-1)) -> 1354.0771
... A63: 60 | B63: 2031 | C63: 12 | D63: ='00_통제변수'!$E$16*(1+'00_통제변수'!$E$17)^(A63-1) -> 10.050683 | E63: =E62+D63 -> 1065.8229 | F63: ='00_통제변수'!$E$18+('00_통제변수'!$E$19-'00_통제변수'!$E$18)*MIN(1,MAX(0,(A63-'00_통제변수'!$E$20+1)/MAX(1,'00_통제변수'!$E$21))) -> 0.12 | G63: =E62*F63 -> 126.69267 | H63: =D63+G63 -> 136.74335 | I63: ='00_통제변수'!$E$22+('00_통제변수'!$E$23-'00_통제변수'!$E$22)*MIN(1,MAX(0,(A63-'00_통제변수'!$E$24+1)/MAX(1,'00_통제변수'!$E$25))) -> 1.55 | J63: =H63*I63 -> 211.9522 | K63: =IF(A63>='00_통제변수'!$E$28,'00_통제변수'!$E$27,'00_통제변수'!$E$26) -> 31846 | L63: =J63*K63/10000 -> 674.98297 | M63: =L63/(1-'00_통제변수'!$B$8)*'00_통제변수'!$B$11 -> 719.59805 | N63: =E63*('00_통제변수'!$B$9+('00_통제변수'!$B$10-'00_통제변수'!$B$9)*(A63-1)/MAX(1,'00_통제변수'!$B$6-1)) -> 1918.4813

Sheet 04_회원확대
A1: ④ 회원 확대 (외국인)
A2: 모든 값은 00_통제변수 시트에서 결정됩니다. 이 시트는 수정하지 마십시오.
A3: 월차 | B3: 연도 | C3: 월 | D3: 신규 구매고객 (만명) | E3: 누적 구매고객 (만명) | F3: 잔존율 | G3: 기존 활동 (만명) | H3: 활동 구매고객 (만명) | I3: 구매빈도 (건/월) | J3: 구매건수 (만건) | K3: 객단가 (원) | L3: 택배매출 (억원) | M3: 총매출 (억원) | N3: 회원수 (만명) | O3: 외국인 신규 (만명) | P3: 외국인 누적 (만명) | Q3: 외국인 활동 (만명) | R3: 외국인 건수 (만건) | S3: 외국인 매출 (억원)
A4: 1 | B4: 2027 | C4: 1 | D4: ='00_통제변수'!$F$16*(1+'00_통제변수'!$F$17)^(A4-1) -> 12 | E4: ='00_통제변수'!$B$7+D4 -> 418 | F4: ='00_통제변수'!$F$18+('00_통제변수'!$F$19-'00_통제변수'!$F$18)*MIN(1,MAX(0,(A4-'00_통제변수'!$F$20+1)/MAX(1,'00_통제변수'!$F$21))) -> 0.105 | G4: ='00_통제변수'!$B$7*F4 -> 42.63 | H4: =D4+G4 -> 54.63 | I4: ='00_통제변수'!$F$22+('00_통제변수'!$F$23-'00_통제변수'!$F$22)*MIN(1,MAX(0,(A4-'00_통제변수'!$F$24+1)/MAX(1,'00_통제변수'!$F$25))) -> 1.289 | J4: =H4*I4 -> 70.41807 | K4: =IF(A4>='00_통제변수'!$F$28,'00_통제변수'!$F$27,'00_통제변수'!$F$26) -> 31846 | L4: =J4*K4/10000 -> 224.25339 | M4: =(L4+S4)/(1-'00_통제변수'!$B$8)*'00_통제변수'!$B$11 -> 239.0761 | N4: =(E4+P4)*('00_통제변수'!$B$9+('00_통제변수'!$B$10-'00_통제변수'!$B$9)*(A4-1)/MAX(1,'00_통제변수'!$B$6-1)) -> 1078.44 | O4: =IF(A4>='00_통제변수'!$B$32,'00_통제변수'!$B$33/10000,0) -> 0 | P4: =O4 -> 0 | Q4: =O4 -> 0 | R4: =Q4*'00_통제변수'!$B$36 -> 0 | S4: =R4*'00_통제변수'!$B$35/10000 -> 0
A5: 2 | B5: 2027 | C5: 2 | D5: ='00_통제변수'!$F$16*(1+'00_통제변수'!$F$17)^(A5-1) -> 11.94 | E5: =E4+D5 -> 429.94 | F5: ='00_통제변수'!$F$18+('00_통제변수'!$F$19-'00_통제변수'!$F$18)*MIN(1,MAX(0,(A5-'00_통제변수'!$F$20+1)/MAX(1,'00_통제변수'!$F$21))) -> 0.105 | G5: =E4*F5 -> 43.89 | H5: =D5+G5 -> 55.83 | I5: ='00_통제변수'!$F$22+('00_통제변수'!$F$23-'00_통제변수'!$F$22)*MIN(1,MAX(0,(A5-'00_통제변수'!$F$24+1)/MAX(1,'00_통제변수'!$F$25))) -> 1.289 | J5: =H5*I5 -> 71.96487 | K5: =IF(A5>='00_통제변수'!$F$28,'00_통제변수'!$F$27,'00_통제변수'!$F$26) -> 31846 | L5: =J5*K5/10000 -> 229.17933 | M5: =(L5+S5)/(1-'00_통제변수'!$B$8)*'00_통제변수'!$B$11 -> 244.32764 | N5: =(E5+P5)*('00_통제변수'!$B$9+('00_통제변수'!$B$10-'00_통제변수'!$B$9)*(A5-1)/MAX(1,'00_통제변수'!$B$6-1)) -> 1103.5612 | O5: =IF(A5>='00_통제변수'!$B$32,'00_통제변수'!$B$33/10000,0) -> 0 | P5: =P4+O5 -> 0 | Q5: =O5+P4*'00_통제변수'!$B$34 -> 0 | R5: =Q5*'00_통제변수'!$B$36 -> 0 | S5: =R5*'00_통제변수'!$B$35/10000 -> 0
A6: 3 | B6: 2027 | C6: 3 | D6: ='00_통제변수'!$F$16*(1+'00_통제변수'!$F$17)^(A6-1) -> 11.8803 | E6: =E5+D6 -> 441.8203 | F6: ='00_통제변수'!$F$18+('00_통제변수'!$F$19-'00_통제변수'!$F$18)*MIN(1,MAX(0,(A6-'00_통제변수'!$F$20+1)/MAX(1,'00_통제변수'!$F$21))) -> 0.105 | G6: =E5*F6 -> 45.1437 | H6: =D6+G6 -> 57.024 | I6: ='00_통제변수'!$F$22+('00_통제변수'!$F$23-'00_통제변수'!$F$22)*MIN(1,MAX(0,(A6-'00_통제변수'!$F$24+1)/MAX(1,'00_통제변수'!$F$25))) -> 1.289 | J6: =H6*I6 -> 73.503936 | K6: =IF(A6>='00_통제변수'!$F$28,'00_통제변수'!$F$27,'00_통제변수'!$F$26) -> 31846 | L6: =J6*K6/10000 -> 234.08063 | M6: =(L6+S6)/(1-'00_통제변수'!$B$8)*'00_통제변수'!$B$11 -> 249.55292 | N6: =(E6+P6)*('00_통제변수'!$B$9+('00_통제변수'!$B$10-'00_통제변수'!$B$9)*(A6-1)/MAX(1,'00_통제변수'!$B$6-1)) -> 1128.2143 | O6: =IF(A6>='00_통제변수'!$B$32,'00_통제변수'!$B$33/10000,0) -> 0 | P6: =P5+O6 -> 0 | Q6: =O6+P5*'00_통제변수'!$B$34 -> 0 | R6: =Q6*'00_통제변수'!$B$36 -> 0 | S6: =R6*'00_통제변수'!$B$35/10000 -> 0
A7: 4 | B7: 2027 | C7: 4 | D7: ='00_통제변수'!$F$16*(1+'00_통제변수'!$F$17)^(A7-1) -> 11.820899 | E7: =E6+D7 -> 453.6412 | F7: ='00_통제변수'!$F$18+('00_통제변수'!$F$19-'00_통제변수'!$F$18)*MIN(1,MAX(0,(A7-'00_통제변수'!$F$20+1)/MAX(1,'00_통제변수'!$F$21))) -> 0.105 | G7: =E6*F7 -> 46.391131 | H7: =D7+G7 -> 58.21203 | I7: ='00_통제변수'!$F$22+('00_통제변수'!$F$23-'00_통제변수'!$F$22)*MIN(1,MAX(0,(A7-'00_통제변수'!$F$24+1)/MAX(1,'00_통제변수'!$F$25))) -> 1.289 | J7: =H7*I7 -> 75.035307 | K7: =IF(A7>='00_통제변수'!$F$28,'00_통제변수'!$F$27,'00_통제변수'!$F$26) -> 31846 | L7: =J7*K7/10000 -> 238.95744 | M7: =(L7+S7)/(1-'00_통제변수'!$B$8)*'00_통제변수'!$B$11 -> 254.75207 | N7: =(E7+P7)*('00_통제변수'!$B$9+('00_통제변수'!$B$10-'00_통제변수'!$B$9)*(A7-1)/MAX(1,'00_통제변수'!$B$6-1)) -> 1152.4024 | O7: =IF(A7>='00_통제변수'!$B$32,'00_통제변수'!$B$33/10000,0) -> 0 | P7: =P6+O7 -> 0 | Q7: =O7+P6*'00_통제변수'!$B$34 -> 0 | R7: =Q7*'00_통제변수'!$B$36 -> 0 | S7: =R7*'00_통제변수'!$B$35/10000 -> 0
A8: 5 | B8: 2027 | C8: 5 | D8: ='00_통제변수'!$F$16*(1+'00_통제변수'!$F$17)^(A8-1) -> 11.761794 | E8: =E7+D8 -> 465.40299 | F8: ='00_통제변수'!$F$18+('00_통제변수'!$F$19-'00_통제변수'!$F$18)*MIN(1,MAX(0,(A8-'00_통제변수'!$F$20+1)/MAX(1,'00_통제변수'!$F$21))) -> 0.105 | G8: =E7*F8 -> 47.632326 | H8: =D8+G8 -> 59.39412 | I8: ='00_통제변수'!$F$22+('00_통제변수'!$F$23-'00_통제변수'!$F$22)*MIN(1,MAX(0,(A8-'00_통제변수'!$F$24+1)/MAX(1,'00_통제변수'!$F$25))) -> 1.289 | J8: =H8*I8 -> 76.55902 | K8: =IF(A8>='00_통제변수'!$F$28,'00_통제변수'!$F$27,'00_통제변수'!$F$26) -> 31846 | L8: =J8*K8/10000 -> 243.80986 | M8: =(L8+S8)/(1-'00_통제변수'!$B$8)*'00_통제변수'!$B$11 -> 259.92522 | N8: =(E8+P8)*('00_통제변수'!$B$9+('00_통제변수'!$B$10-'00_통제변수'!$B$9)*(A8-1)/MAX(1,'00_통제변수'!$B$6-1)) -> 1176.1286 | O8: =IF(A8>='00_통제변수'!$B$32,'00_통제변수'!$B$33/10000,0) -> 0 | P8: =P7+O8 -> 0 | Q8: =O8+P7*'00_통제변수'!$B$34 -> 0 | R8: =Q8*'00_통제변수'!$B$36 -> 0 | S8: =R8*'00_통제변수'!$B$35/10000 -> 0
A9: 6 | B9: 2027 | C9: 6 | D9: ='00_통제변수'!$F$16*(1+'00_통제변수'!$F$17)^(A9-1) -> 11.702985 | E9: =E8+D9 -> 477.10598 | F9: ='00_통제변수'!$F$18+('00_통제변수'!$F$19-'00_통제변수'!$F$18)*MIN(1,MAX(0,(A9-'00_통제변수'!$F$20+1)/MAX(1,'00_통제변수'!$F$21))) -> 0.105 | G9: =E8*F9 -> 48.867314 | H9: =D9+G9 -> 60.570299 | I9: ='00_통제변수'!$F$22+('00_통제변수'!$F$23-'00_통제변수'!$F$22)*MIN(1,MAX(0,(A9-'00_통제변수'!$F$24+1)/MAX(1,'00_통제변수'!$F$25))) -> 1.289 | J9: =H9*I9 -> 78.075116 | K9: =IF(A9>='00_통제변수'!$F$28,'00_통제변수'!$F$27,'00_통제변수'!$F$26) -> 31846 | L9: =J9*K9/10000 -> 248.63801 | M9: =(L9+S9)/(1-'00_통제변수'!$B$8)*'00_통제변수'!$B$11 -> 265.07251 | N9: =(E9+P9)*('00_통제변수'!$B$9+('00_통제변수'!$B$10-'00_통제변수'!$B$9)*(A9-1)/MAX(1,'00_통제변수'!$B$6-1)) -> 1199.3959 | O9: =IF(A9>='00_통제변수'!$B$32,'00_통제변수'!$B$33/10000,0) -> 0 | P9: =P8+O9 -> 0 | Q9: =O9+P8*'00_통제변수'!$B$34 -> 0 | R9: =Q9*'00_통제변수'!$B$36 -> 0 | S9: =R9*'00_통제변수'!$B$35/10000 -> 0
A10: 7 | B10: 2027 | C10: 7 | D10: ='00_통제변수'!$F$16*(1+'00_통제변수'!$F$17)^(A10-1) -> 11.64447 | E10: =E9+D10 -> 488.75045 | F10: ='00_통제변수'!$F$18+('00_통제변수'!$F$19-'00_통제변수'!$F$18)*MIN(1,MAX(0,(A10-'00_통제변수'!$F$20+1)/MAX(1,'00_통제변수'!$F$21))) -> 0.105 | G10: =E9*F10 -> 50.096128 | H10: =D10+G10 -> 61.740598 | I10: ='00_통제변수'!$F$22+('00_통제변수'!$F$23-'00_통제변수'!$F$22)*MIN(1,MAX(0,(A10-'00_통제변수'!$F$24+1)/MAX(1,'00_통제변수'!$F$25))) -> 1.289 | J10: =H10*I10 -> 79.583631 | K10: =IF(A10>='00_통제변수'!$F$28,'00_통제변수'!$F$27,'00_통제변수'!$F$26) -> 31846 | L10: =J10*K10/10000 -> 253.44203 | M10: =(L10+S10)/(1-'00_통제변수'!$B$8)*'00_통제변수'!$B$11 -> 270.19406 | N10: =(E10+P10)*('00_통제변수'!$B$9+('00_통제변수'!$B$10-'00_통제변수'!$B$9)*(A10-1)/MAX(1,'00_통제변수'!$B$6-1)) -> 1222.2075 | O10: =IF(A10>='00_통제변수'!$B$32,'00_통제변수'!$B$33/10000,0) -> 0 | P10: =P9+O10 -> 0 | Q10: =O10+P9*'00_통제변수'!$B$34 -> 0 | R10: =Q10*'00_통제변수'!$B$36 -> 0 | S10: =R10*'00_통제변수'!$B$35/10000 -> 0
A11: 8 | B11: 2027 | C11: 8 | D11: ='00_통제변수'!$F$16*(1+'00_통제변수'!$F$17)^(A11-1) -> 11.586248 | E11: =E10+D11 -> 500.3367 | F11: ='00_통제변수'!$F$18+('00_통제변수'!$F$19-'00_통제변수'!$F$18)*MIN(1,MAX(0,(A11-'00_통제변수'!$F$20+1)/MAX(1,'00_통제변수'!$F$21))) -> 0.105 | G11: =E10*F11 -> 51.318797 | H11: =D11+G11 -> 62.905045 | I11: ='00_통제변수'!$F$22+('00_통제변수'!$F$23-'00_통제변수'!$F$22)*MIN(1,MAX(0,(A11-'00_통제변수'!$F$24+1)/MAX(1,'00_통제변수'!$F$25))) -> 1.289 | J11: =H11*I11 -> 81.084603 | K11: =IF(A11>='00_통제변수'!$F$28,'00_통제변수'!$F$27,'00_통제변수'!$F$26) -> 31846 | L11: =J11*K11/10000 -> 258.22203 | M11: =(L11+S11)/(1-'00_통제변수'!$B$8)*'00_통제변수'!$B$11 -> 275.29001 | N11: =(E11+P11)*('00_통제변수'!$B$9+('00_통제변수'!$B$10-'00_통제변수'!$B$9)*(A11-1)/MAX(1,'00_통제변수'!$B$6-1)) -> 1244.5663 | O11: =IF(A11>='00_통제변수'!$B$32,'00_통제변수'!$B$33/10000,0) -> 0 | P11: =P10+O11 -> 0 | Q11: =O11+P10*'00_통제변수'!$B$34 -> 0 | R11: =Q11*'00_통제변수'!$B$36 -> 0 | S11: =R11*'00_통제변수'!$B$35/10000 -> 0
A12: 9 | B12: 2027 | C12: 9 | D12: ='00_통제변수'!$F$16*(1+'00_통제변수'!$F$17)^(A12-1) -> 11.528317 | E12: =E11+D12 -> 511.86501 | F12: ='00_통제변수'!$F$18+('00_통제변수'!$F$19-'00_통제변수'!$F$18)*MIN(1,MAX(0,(A12-'00_통제변수'!$F$20+1)/MAX(1,'00_통제변수'!$F$21))) -> 0.105 | G12: =E11*F12 -> 52.535353 | H12: =D12+G12 -> 64.06367 | I12: ='00_통제변수'!$F$22+('00_통제변수'!$F$23-'00_통제변수'!$F$22)*MIN(1,MAX(0,(A12-'00_통제변수'!$F$24+1)/MAX(1,'00_통제변수'!$F$25))) -> 1.289 | J12: =H12*I12 -> 82.57807 | K12: =IF(A12>='00_통제변수'!$F$28,'00_통제변수'!$F$27,'00_통제변수'!$F$26) -> 31846 | L12: =J12*K12/10000 -> 262.97812 | M12: =(L12+S12)/(1-'00_통제변수'!$B$8)*'00_통제변수'!$B$11 -> 287.07689 | N12: =(E12+P12)*('00_통제변수'!$B$9+('00_통제변수'!$B$10-'00_통제변수'!$B$9)*(A12-1)/MAX(1,'00_통제변수'!$B$6-1)) -> 1268.9497 | O12: =IF(A12>='00_통제변수'!$B$32,'00_통제변수'!$B$33/10000,0) -> 1 | P12: =P11+O12 -> 1 | Q12: =O12+P11*'00_통제변수'!$B$34 -> 1 | R12: =Q12*'00_통제변수'!$B$36 -> 1.05 | S12: =R12*'00_통제변수'!$B$35/10000 -> 6.3
A13: 10 | B13: 2027 | C13: 10 | D13: ='00_통제변수'!$F$16*(1+'00_통제변수'!$F$17)^(A13-1) -> 11.470675 | E13: =E12+D13 -> 523.33569 | F13: ='00_통제변수'!$F$18+('00_통제변수'!$F$19-'00_통제변수'!$F$18)*MIN(1,MAX(0,(A13-'00_통제변수'!$F$20+1)/MAX(1,'00_통제변수'!$F$21))) -> 0.105 | G13: =E12*F13 -> 53.745826 | H13: =D13+G13 -> 65.216501 | I13: ='00_통제변수'!$F$22+('00_통제변수'!$F$23-'00_통제변수'!$F$22)*MIN(1,MAX(0,(A13-'00_통제변수'!$F$24+1)/MAX(1,'00_통제변수'!$F$25))) -> 1.289 | J13: =H13*I13 -> 84.06407 | K13: =IF(A13>='00_통제변수'!$F$28,'00_통제변수'!$F$27,'00_통제변수'!$F$26) -> 31846 | L13: =J13*K13/10000 -> 267.71044 | M13: =(L13+S13)/(1-'00_통제변수'!$B$8)*'00_통제변수'!$B$11 -> 292.32349 | N13: =(E13+P13)*('00_통제변수'!$B$9+('00_통제변수'!$B$10-'00_통제변수'!$B$9)*(A13-1)/MAX(1,'00_통제변수'!$B$6-1)) -> 1292.86 | O13: =IF(A13>='00_통제변수'!$B$32,'00_통제변수'!$B$33/10000,0) -> 1 | P13: =P12+O13 -> 2 | Q13: =O13+P12*'00_통제변수'!$B$34 -> 1.03 | R13: =Q13*'00_통제변수'!$B$36 -> 1.0815 | S13: =R13*'00_통제변수'!$B$35/10000 -> 6.489
A14: 11 | B14: 2027 | C14: 11 | D14: ='00_통제변수'!$F$16*(1+'00_통제변수'!$F$17)^(A14-1) -> 11.413322 | E14: =E13+D14 -> 534.74901 | F14: ='00_통제변수'!$F$18+('00_통제변수'!$F$19-'00_통제변수'!$F$18)*MIN(1,MAX(0,(A14-'00_통제변수'!$F$20+1)/MAX(1,'00_통제변수'!$F$21))) -> 0.105 | G14: =E13*F14 -> 54.950247 | H14: =D14+G14 -> 66.363569 | I14: ='00_통제변수'!$F$22+('00_통제변수'!$F$23-'00_통제변수'!$F$22)*MIN(1,MAX(0,(A14-'00_통제변수'!$F$24+1)/MAX(1,'00_통제변수'!$F$25))) -> 1.289 | J14: =H14*I14 -> 85.54264 | K14: =IF(A14>='00_통제변수'!$F$28,'00_통제변수'!$F$27,'00_통제변수'!$F$26) -> 31846 | L14: =J14*K14/10000 -> 272.41909 | M14: =(L14+S14)/(1-'00_통제변수'!$B$8)*'00_통제변수'!$B$11 -> 297.54487 | N14: =(E14+P14)*('00_통제변수'!$B$9+('00_통제변수'!$B$10-'00_통제변수'!$B$9)*(A14-1)/MAX(1,'00_통제변수'!$B$6-1)) -> 1316.3002 | O14: =IF(A14>='00_통제변수'!$B$32,'00_통제변수'!$B$33/10000,0) -> 1 | P14: =P13+O14 -> 3 | Q14: =O14+P13*'00_통제변수'!$B$34 -> 1.06 | R14: =Q14*'00_통제변수'!$B$36 -> 1.113 | S14: =R14*'00_통제변수'!$B$35/10000 -> 6.678
A15: 12 | B15: 2027 | C15: 12 | D15: ='00_통제변수'!$F$16*(1+'00_통제변수'!$F$17)^(A15-1) -> 11.356255 | E15: =E14+D15 -> 546.10526 | F15: ='00_통제변수'!$F$18+('00_통제변수'!$F$19-'00_통제변수'!$F$18)*MIN(1,MAX(0,(A15-'00_통제변수'!$F$20+1)/MAX(1,'00_통제변수'!$F$21))) -> 0.105 | G15: =E14*F15 -> 56.148646 | H15: =D15+G15 -> 67.504901 | I15: ='00_통제변수'!$F$22+('00_통제변수'!$F$23-'00_통제변수'!$F$22)*MIN(1,MAX(0,(A15-'00_통제변수'!$F$24+1)/MAX(1,'00_통제변수'!$F$25))) -> 1.289 | J15: =H15*I15 -> 87.013817 | K15: =IF(A15>='00_통제변수'!$F$28,'00_통제변수'!$F$27,'00_통제변수'!$F$26) -> 31846 | L15: =J15*K15/10000 -> 277.1042 | M15: =(L15+S15)/(1-'00_통제변수'!$B$8)*'00_통제변수'!$B$11 -> 302.74115 | N15: =(E15+P15)*('00_통제변수'!$B$9+('00_통제변수'!$B$10-'00_통제변수'!$B$9)*(A15-1)/MAX(1,'00_통제변수'!$B$6-1)) -> 1339.2732 | O15: =IF(A15>='00_통제변수'!$B$32,'00_통제변수'!$B$33/10000,0) -> 1 | P15: =P14+O15 -> 4 | Q15: =O15+P14*'00_통제변수'!$B$34 -> 1.09 | R15: =Q15*'00_통제변수'!$B$36 -> 1.1445 | S15: =R15*'00_통제변수'!$B$35/10000 -> 6.867
A16: 13 | B16: 2028 | C16: 1 | D16: ='00_통제변수'!$F$16*(1+'00_통제변수'!$F$17)^(A16-1) -> 11.299474 | E16: =E15+D16 -> 557.40474 | F16: ='00_통제변수'!$F$18+('00_통제변수'!$F$19-'00_통제변수'!$F$18)*MIN(1,MAX(0,(A16-'00_통제변수'!$F$20+1)/MAX(1,'00_통제변수'!$F$21))) -> 0.105 | G16: =E15*F16 -> 57.341053 | H16: =D16+G16 -> 68.640526 | I16: ='00_통제변수'!$F$22+('00_통제변수'!$F$23-'00_통제변수'!$F$22)*MIN(1,MAX(0,(A16-'00_통제변수'!$F$24+1)/MAX(1,'00_통제변수'!$F$25))) -> 1.289 | J16: =H16*I16 -> 88.477638 | K16: =IF(A16>='00_통제변수'!$F$28,'00_통제변수'!$F$27,'00_통제변수'!$F$26) -> 31846 | L16: =J16*K16/10000 -> 281.76589 | M16: =(L16+S16)/(1-'00_통제변수'!$B$8)*'00_통제변수'!$B$11 -> 307.91246 | N16: =(E16+P16)*('00_통제변수'!$B$9+('00_통제변수'!$B$10-'00_통제변수'!$B$9)*(A16-1)/MAX(1,'00_통제변수'!$B$6-1)) -> 1361.782 | O16: =IF(A16>='00_통제변수'!$B$32,'00_통제변수'!$B$33/10000,0) -> 1 | P16: =P15+O16 -> 5 | Q16: =O16+P15*'00_통제변수'!$B$34 -> 1.12 | R16: =Q16*'00_통제변수'!$B$36 -> 1.176 | S16: =R16*'00_통제변수'!$B$35/10000 -> 7.056
... A63: 60 | B63: 2031 | C63: 12 | D63: ='00_통제변수'!$F$16*(1+'00_통제변수'!$F$17)^(A63-1) -> 8.9277703 | E63: =E62+D63 -> 1029.3737 | F63: ='00_통제변수'!$F$18+('00_통제변수'!$F$19-'00_통제변수'!$F$18)*MIN(1,MAX(0,(A63-'00_통제변수'!$F$20+1)/MAX(1,'00_통제변수'!$F$21))) -> 0.105 | G63: =E62*F63 -> 107.14682 | H63: =D63+G63 -> 116.07459 | I63: ='00_통제변수'!$F$22+('00_통제변수'!$F$23-'00_통제변수'!$F$22)*MIN(1,MAX(0,(A63-'00_통제변수'!$F$24+1)/MAX(1,'00_통제변수'!$F$25))) -> 1.289 | J63: =H63*I63 -> 149.62015 | K63: =IF(A63>='00_통제변수'!$F$28,'00_통제변수'!$F$27,'00_통제변수'!$F$26) -> 31846 | L63: =J63*K63/10000 -> 476.48033 | M63: =(L63+S63)/(1-'00_통제변수'!$B$8)*'00_통제변수'!$B$11 -> 524.9673 | N63: =(E63+P63)*('00_통제변수'!$B$9+('00_통제변수'!$B$10-'00_통제변수'!$B$9)*(A63-1)/MAX(1,'00_통제변수'!$B$6-1)) -> 1946.4727 | O63: =IF(A63>='00_통제변수'!$B$32,'00_통제변수'!$B$33/10000,0) -> 1 | P63: =P62+O63 -> 52 | Q63: =O63+P62*'00_통제변수'!$B$34 -> 2.53 | R63: =Q63*'00_통제변수'!$B$36 -> 2.6565 | S63: =R63*'00_통제변수'!$B$35/10000 -> 15.939

Sheet 05_요약
A1: 시나리오 비교 요약
A2: 연도별 주요 지표. 값은 00_통제변수 시트의 입력에 따라 자동으로 바뀝니다.
A4: 연간 총매출 (억원) | B4: 2027 | C4: 2028 | D4: 2029 | E4: 2030 | F4: 2031
A5: ① 현상유지 | B5: =SUMIFS('01_현상유지'!$M$4:$M$63,'01_현상유지'!$B$4:$B$63,2027) -> 3209.8023 | C5: =SUMIFS('01_현상유지'!$M$4:$M$63,'01_현상유지'!$B$4:$B$63,2028) -> 3925.6698 | D5: =SUMIFS('01_현상유지'!$M$4:$M$63,'01_현상유지'!$B$4:$B$63,2029) -> 4599.7469 | E5: =SUMIFS('01_현상유지'!$M$4:$M$63,'01_현상유지'!$B$4:$B$63,2030) -> 5234.4733 | F5: =SUMIFS('01_현상유지'!$M$4:$M$63,'01_현상유지'!$B$4:$B$63,2031) -> 5832.1462
A6: ② 물류혁신 (무배 인하 + 완전 익일배송) | B6: =SUMIFS('02_무배+익일'!$M$4:$M$63,'02_무배+익일'!$B$4:$B$63,2027) -> 3138.7446 | C6: =SUMIFS('02_무배+익일'!$M$4:$M$63,'02_무배+익일'!$B$4:$B$63,2028) -> 4449.5282 | D6: =SUMIFS('02_무배+익일'!$M$4:$M$63,'02_무배+익일'!$B$4:$B$63,2029) -> 6512.7251 | E6: =SUMIFS('02_무배+익일'!$M$4:$M$63,'02_무배+익일'!$B$4:$B$63,2030) -> 8497.4391 | F6: =SUMIFS('02_무배+익일'!$M$4:$M$63,'02_무배+익일'!$B$4:$B$63,2031) -> 9943.5193
A7: ③ 물류혁신 (완전 익일배송) | B7: =SUMIFS('03_익일배송'!$M$4:$M$63,'03_익일배송'!$B$4:$B$63,2027) -> 3414.9343 | C7: =SUMIFS('03_익일배송'!$M$4:$M$63,'03_익일배송'!$B$4:$B$63,2028) -> 4485.3219 | D7: =SUMIFS('03_익일배송'!$M$4:$M$63,'03_익일배송'!$B$4:$B$63,2029) -> 5661.4863 | E7: =SUMIFS('03_익일배송'!$M$4:$M$63,'03_익일배송'!$B$4:$B$63,2030) -> 6929.0264 | F7: =SUMIFS('03_익일배송'!$M$4:$M$63,'03_익일배송'!$B$4:$B$63,2031) -> 8189.0421
A8: ④ 회원 확대 (외국인) | B8: =SUMIFS('04_회원확대'!$M$4:$M$63,'04_회원확대'!$B$4:$B$63,2027) -> 3237.8769 | C8: =SUMIFS('04_회원확대'!$M$4:$M$63,'04_회원확대'!$B$4:$B$63,2028) -> 4029.2369 | D8: =SUMIFS('04_회원확대'!$M$4:$M$63,'04_회원확대'!$B$4:$B$63,2029) -> 4732.329 | E8: =SUMIFS('04_회원확대'!$M$4:$M$63,'04_회원확대'!$B$4:$B$63,2030) -> 5396.0703 | F8: =SUMIFS('04_회원확대'!$M$4:$M$63,'04_회원확대'!$B$4:$B$63,2031) -> 6022.7581
A10: 연간 택배매출 (억원) | B10: 2027 | C10: 2028 | D10: 2029 | E10: 2030 | F10: 2031
A11: ① 현상유지 | B11: =SUMIFS('01_현상유지'!$L$4:$L$63,'01_현상유지'!$B$4:$B$63,2027) -> 3010.7946 | C11: =SUMIFS('01_현상유지'!$L$4:$L$63,'01_현상유지'!$B$4:$B$63,2028) -> 3682.2782 | D11: =SUMIFS('01_현상유지'!$L$4:$L$63,'01_현상유지'!$B$4:$B$63,2029) -> 4314.5626 | E11: =SUMIFS('01_현상유지'!$L$4:$L$63,'01_현상유지'!$B$4:$B$63,2030) -> 4909.936 | F11: =SUMIFS('01_현상유지'!$L$4:$L$63,'01_현상유지'!$B$4:$B$63,2031) -> 5470.5531
A12: ② 물류혁신 (무배 인하 + 완전 익일배송) | B12: =SUMIFS('02_무배+익일'!$L$4:$L$63,'02_무배+익일'!$B$4:$B$63,2027) -> 2944.1424 | C12: =SUMIFS('02_무배+익일'!$L$4:$L$63,'02_무배+익일'!$B$4:$B$63,2028) -> 4173.6574 | D12: =SUMIFS('02_무배+익일'!$L$4:$L$63,'02_무배+익일'!$B$4:$B$63,2029) -> 6108.9361 | E12: =SUMIFS('02_무배+익일'!$L$4:$L$63,'02_무배+익일'!$B$4:$B$63,2030) -> 7970.5979 | F12: =SUMIFS('02_무배+익일'!$L$4:$L$63,'02_무배+익일'!$B$4:$B$63,2031) -> 9327.0211
A13: ③ 물류혁신 (완전 익일배송) | B13: =SUMIFS('03_익일배송'!$L$4:$L$63,'03_익일배송'!$B$4:$B$63,2027) -> 3203.2084 | C13: =SUMIFS('03_익일배송'!$L$4:$L$63,'03_익일배송'!$B$4:$B$63,2028) -> 4207.232 | D13: =SUMIFS('03_익일배송'!$L$4:$L$63,'03_익일배송'!$B$4:$B$63,2029) -> 5310.4741 | E13: =SUMIFS('03_익일배송'!$L$4:$L$63,'03_익일배송'!$B$4:$B$63,2030) -> 6499.4268 | F13: =SUMIFS('03_익일배송'!$L$4:$L$63,'03_익일배송'!$B$4:$B$63,2031) -> 7681.3215
A14: ④ 회원 확대 (외국인) | B14: =SUMIFS('04_회원확대'!$L$4:$L$63,'04_회원확대'!$B$4:$B$63,2027) -> 3010.7946 | C14: =SUMIFS('04_회원확대'!$L$4:$L$63,'04_회원확대'!$B$4:$B$63,2028) -> 3682.2782 | D14: =SUMIFS('04_회원확대'!$L$4:$L$63,'04_회원확대'!$B$4:$B$63,2029) -> 4314.5626 | E14: =SUMIFS('04_회원확대'!$L$4:$L$63,'04_회원확대'!$B$4:$B$63,2030) -> 4909.936 | F14: =SUMIFS('04_회원확대'!$L$4:$L$63,'04_회원확대'!$B$4:$B$63,2031) -> 5470.5531
A16: 연간 구매건수 (만건) | B16: 2027 | C16: 2028 | D16: 2029 | E16: 2030 | F16: 2031
A17: ① 현상유지 | B17: =SUMIFS('01_현상유지'!$J$4:$J$63,'01_현상유지'!$B$4:$B$63,2027) -> 945.42315 | C17: =SUMIFS('01_현상유지'!$J$4:$J$63,'01_현상유지'!$B$4:$B$63,2028) -> 1156.2765 | D17: =SUMIFS('01_현상유지'!$J$4:$J$63,'01_현상유지'!$B$4:$B$63,2029) -> 1354.8209 | E17: =SUMIFS('01_현상유지'!$J$4:$J$63,'01_현상유지'!$B$4:$B$63,2030) -> 1541.7748 | F17: =SUMIFS('01_현상유지'!$J$4:$J$63,'01_현상유지'!$B$4:$B$63,2031) -> 1717.8148
A18: ② 물류혁신 (무배 인하 + 완전 익일배송) | B18: =SUMIFS('02_무배+익일'!$J$4:$J$63,'02_무배+익일'!$B$4:$B$63,2027) -> 1045.8443 | C18: =SUMIFS('02_무배+익일'!$J$4:$J$63,'02_무배+익일'!$B$4:$B$63,2028) -> 1605.2529 | D18: =SUMIFS('02_무배+익일'!$J$4:$J$63,'02_무배+익일'!$B$4:$B$63,2029) -> 2349.5908 | E18: =SUMIFS('02_무배+익일'!$J$4:$J$63,'02_무배+익일'!$B$4:$B$63,2030) -> 3065.6146 | F18: =SUMIFS('02_무배+익일'!$J$4:$J$63,'02_무배+익일'!$B$4:$B$63,2031) -> 3587.3158
A19: ③ 물류혁신 (완전 익일배송) | B19: =SUMIFS('03_익일배송'!$J$4:$J$63,'03_익일배송'!$B$4:$B$63,2027) -> 1005.8432 | C19: =SUMIFS('03_익일배송'!$J$4:$J$63,'03_익일배송'!$B$4:$B$63,2028) -> 1321.1179 | D19: =SUMIFS('03_익일배송'!$J$4:$J$63,'03_익일배송'!$B$4:$B$63,2029) -> 1667.5482 | E19: =SUMIFS('03_익일배송'!$J$4:$J$63,'03_익일배송'!$B$4:$B$63,2030) -> 2040.8927 | F19: =SUMIFS('03_익일배송'!$J$4:$J$63,'03_익일배송'!$B$4:$B$63,2031) -> 2412.0208
A20: ④ 회원 확대 (외국인) | B20: =SUMIFS('04_회원확대'!$J$4:$J$63,'04_회원확대'!$B$4:$B$63,2027) -> 945.42315 | C20: =SUMIFS('04_회원확대'!$J$4:$J$63,'04_회원확대'!$B$4:$B$63,2028) -> 1156.2765 | D20: =SUMIFS('04_회원확대'!$J$4:$J$63,'04_회원확대'!$B$4:$B$63,2029) -> 1354.8209 | E20: =SUMIFS('04_회원확대'!$J$4:$J$63,'04_회원확대'!$B$4:$B$63,2030) -> 1541.7748 | F20: =SUMIFS('04_회원확대'!$J$4:$J$63,'04_회원확대'!$B$4:$B$63,2031) -> 1717.8148
A22: 12월 월매출 (억원) | B22: 2027 | C22: 2028 | D22: 2029 | E22: 2030 | F22: 2031
A23: ① 현상유지 | B23: =SUMIFS('01_현상유지'!$M$4:$M$63,'01_현상유지'!$B$4:$B$63,2027,'01_현상유지'!$C$4:$C$63,12) -> 295.42026 | C23: =SUMIFS('01_현상유지'!$M$4:$M$63,'01_현상유지'!$B$4:$B$63,2028,'01_현상유지'!$C$4:$C$63,12) -> 353.44501 | D23: =SUMIFS('01_현상유지'!$M$4:$M$63,'01_현상유지'!$B$4:$B$63,2029,'01_현상유지'!$C$4:$C$63,12) -> 408.08244 | E23: =SUMIFS('01_현상유지'!$M$4:$M$63,'01_현상유지'!$B$4:$B$63,2030,'01_현상유지'!$C$4:$C$63,12) -> 459.5303 | F23: =SUMIFS('01_현상유지'!$M$4:$M$63,'01_현상유지'!$B$4:$B$63,2031,'01_현상유지'!$C$4:$C$63,12) -> 507.97477
A24: ② 물류혁신 (무배 인하 + 완전 익일배송) | B24: =SUMIFS('02_무배+익일'!$M$4:$M$63,'02_무배+익일'!$B$4:$B$63,2027,'02_무배+익일'!$C$4:$C$63,12) -> 292.78115 | C24: =SUMIFS('02_무배+익일'!$M$4:$M$63,'02_무배+익일'!$B$4:$B$63,2028,'02_무배+익일'!$C$4:$C$63,12) -> 442.8576 | D24: =SUMIFS('02_무배+익일'!$M$4:$M$63,'02_무배+익일'!$B$4:$B$63,2029,'02_무배+익일'!$C$4:$C$63,12) -> 628.97046 | E24: =SUMIFS('02_무배+익일'!$M$4:$M$63,'02_무배+익일'!$B$4:$B$63,2030,'02_무배+익일'!$C$4:$C$63,12) -> 773.50645 | F24: =SUMIFS('02_무배+익일'!$M$4:$M$63,'02_무배+익일'!$B$4:$B$63,2031,'02_무배+익일'!$C$4:$C$63,12) -> 875.08044
A25: ③ 물류혁신 (완전 익일배송) | B25: =SUMIFS('03_익일배송'!$M$4:$M$63,'03_익일배송'!$B$4:$B$63,2027,'03_익일배송'!$C$4:$C$63,12) -> 323.5566 | C25: =SUMIFS('03_익일배송'!$M$4:$M$63,'03_익일배송'!$B$4:$B$63,2028,'03_익일배송'!$C$4:$C$63,12) -> 417.4375 | D25: =SUMIFS('03_익일배송'!$M$4:$M$63,'03_익일배송'!$B$4:$B$63,2029,'03_익일배송'!$C$4:$C$63,12) -> 518.94515 | E25: =SUMIFS('03_익일배송'!$M$4:$M$63,'03_익일배송'!$B$4:$B$63,2030,'03_익일배송'!$C$4:$C$63,12) -> 628.05611 | F25: =SUMIFS('03_익일배송'!$M$4:$M$63,'03_익일배송'!$B$4:$B$63,2031,'03_익일배송'!$C$4:$C$63,12) -> 719.59805
A26: ④ 회원 확대 (외국인) | B26: =SUMIFS('04_회원확대'!$M$4:$M$63,'04_회원확대'!$B$4:$B$63,2027,'04_회원확대'!$C$4:$C$63,12) -> 302.74115 | C26: =SUMIFS('04_회원확대'!$M$4:$M$63,'04_회원확대'!$B$4:$B$63,2028,'04_회원확대'!$C$4:$C$63,12) -> 363.18382 | D26: =SUMIFS('04_회원확대'!$M$4:$M$63,'04_회원확대'!$B$4:$B$63,2029,'04_회원확대'!$C$4:$C$63,12) -> 420.23916 | E26: =SUMIFS('04_회원확대'!$M$4:$M$63,'04_회원확대'!$B$4:$B$63,2030,'04_회원확대'!$C$4:$C$63,12) -> 474.10492 | F26: =SUMIFS('04_회원확대'!$M$4:$M$63,'04_회원확대'!$B$4:$B$63,2031,'04_회원확대'!$C$4:$C$63,12) -> 524.9673
A28: 12월 활동 구매고객 (만명) | B28: 2027 | C28: 2028 | D28: 2029 | E28: 2030 | F28: 2031
A29: ① 현상유지 | B29: =SUMIFS('01_현상유지'!$H$4:$H$63,'01_현상유지'!$B$4:$B$63,2027,'01_현상유지'!$C$4:$C$63,12) -> 67.504901 | C29: =SUMIFS('01_현상유지'!$H$4:$H$63,'01_현상유지'!$B$4:$B$63,2028,'01_현상유지'!$C$4:$C$63,12) -> 80.763827 | D29: =SUMIFS('01_현상유지'!$H$4:$H$63,'01_현상유지'!$B$4:$B$63,2029,'01_현상유지'!$C$4:$C$63,12) -> 93.248734 | E29: =SUMIFS('01_현상유지'!$H$4:$H$63,'01_현상유지'!$B$4:$B$63,2030,'01_현상유지'!$C$4:$C$63,12) -> 105.00481 | F29: =SUMIFS('01_현상유지'!$H$4:$H$63,'01_현상유지'!$B$4:$B$63,2031,'01_현상유지'!$C$4:$C$63,12) -> 116.07459
A30: ② 물류혁신 (무배 인하 + 완전 익일배송) | B30: =SUMIFS('02_무배+익일'!$H$4:$H$63,'02_무배+익일'!$B$4:$B$63,2027,'02_무배+익일'!$C$4:$C$63,12) -> 75.00634 | C30: =SUMIFS('02_무배+익일'!$H$4:$H$63,'02_무배+익일'!$B$4:$B$63,2028,'02_무배+익일'!$C$4:$C$63,12) -> 99.073604 | D30: =SUMIFS('02_무배+익일'!$H$4:$H$63,'02_무배+익일'!$B$4:$B$63,2029,'02_무배+익일'!$C$4:$C$63,12) -> 126.06288 | E30: =SUMIFS('02_무배+익일'!$H$4:$H$63,'02_무배+익일'!$B$4:$B$63,2030,'02_무배+익일'!$C$4:$C$63,12) -> 155.03185 | F30: =SUMIFS('02_무배+익일'!$H$4:$H$63,'02_무배+익일'!$B$4:$B$63,2031,'02_무배+익일'!$C$4:$C$63,12) -> 175.39005
A31: ③ 물류혁신 (완전 익일배송) | B31: =SUMIFS('03_익일배송'!$H$4:$H$63,'03_익일배송'!$B$4:$B$63,2027,'03_익일배송'!$C$4:$C$63,12) -> 71.813623 | C31: =SUMIFS('03_익일배송'!$H$4:$H$63,'03_익일배송'!$B$4:$B$63,2028,'03_익일배송'!$C$4:$C$63,12) -> 88.308536 | D31: =SUMIFS('03_익일배송'!$H$4:$H$63,'03_익일배송'!$B$4:$B$63,2029,'03_익일배송'!$C$4:$C$63,12) -> 104.86782 | E31: =SUMIFS('03_익일배송'!$H$4:$H$63,'03_익일배송'!$B$4:$B$63,2030,'03_익일배송'!$C$4:$C$63,12) -> 121.47865 | F31: =SUMIFS('03_익일배송'!$H$4:$H$63,'03_익일배송'!$B$4:$B$63,2031,'03_익일배송'!$C$4:$C$63,12) -> 136.74335
A32: ④ 회원 확대 (외국인) | B32: =SUMIFS('04_회원확대'!$H$4:$H$63,'04_회원확대'!$B$4:$B$63,2027,'04_회원확대'!$C$4:$C$63,12) -> 67.504901 | C32: =SUMIFS('04_회원확대'!$H$4:$H$63,'04_회원확대'!$B$4:$B$63,2028,'04_회원확대'!$C$4:$C$63,12) -> 80.763827 | D32: =SUMIFS('04_회원확대'!$H$4:$H$63,'04_회원확대'!$B$4:$B$63,2029,'04_회원확대'!$C$4:$C$63,12) -> 93.248734 | E32: =SUMIFS('04_회원확대'!$H$4:$H$63,'04_회원확대'!$B$4:$B$63,2030,'04_회원확대'!$C$4:$C$63,12) -> 105.00481 | F32: =SUMIFS('04_회원확대'!$H$4:$H$63,'04_회원확대'!$B$4:$B$63,2031,'04_회원확대'!$C$4:$C$63,12) -> 116.07459
A34: 12월 누적 구매고객 (만명) | B34: 2027 | C34: 2028 | D34: 2029 | E34: 2030 | F34: 2031
A35: ① 현상유지 | B35: =SUMIFS('01_현상유지'!$E$4:$E$63,'01_현상유지'!$B$4:$B$63,2027,'01_현상유지'!$C$4:$C$63,12) -> 546.10526 | C35: =SUMIFS('01_현상유지'!$E$4:$E$63,'01_현상유지'!$B$4:$B$63,2028,'01_현상유지'!$C$4:$C$63,12) -> 678.03157 | D35: =SUMIFS('01_현상유지'!$E$4:$E$63,'01_현상유지'!$B$4:$B$63,2029,'01_현상유지'!$C$4:$C$63,12) -> 802.2564 | E35: =SUMIFS('01_현상유지'!$E$4:$E$63,'01_현상유지'!$B$4:$B$63,2030,'01_현상유지'!$C$4:$C$63,12) -> 919.22933 | F35: =SUMIFS('01_현상유지'!$E$4:$E$63,'01_현상유지'!$B$4:$B$63,2031,'01_현상유지'!$C$4:$C$63,12) -> 1029.3737
A36: ② 물류혁신 (무배 인하 + 완전 익일배송) | B36: =SUMIFS('02_무배+익일'!$E$4:$E$63,'02_무배+익일'!$B$4:$B$63,2027,'02_무배+익일'!$C$4:$C$63,12) -> 549.21063 | C36: =SUMIFS('02_무배+익일'!$E$4:$E$63,'02_무배+익일'!$B$4:$B$63,2028,'02_무배+익일'!$C$4:$C$63,12) -> 690.71216 | D36: =SUMIFS('02_무배+익일'!$E$4:$E$63,'02_무배+익일'!$B$4:$B$63,2029,'02_무배+익일'!$C$4:$C$63,12) -> 830.52498 | E36: =SUMIFS('02_무배+익일'!$E$4:$E$63,'02_무배+익일'!$B$4:$B$63,2030,'02_무배+익일'!$C$4:$C$63,12) -> 968.66924 | F36: =SUMIFS('02_무배+익일'!$E$4:$E$63,'02_무배+익일'!$B$4:$B$63,2031,'02_무배+익일'!$C$4:$C$63,12) -> 1105.1649
A37: ③ 물류혁신 (완전 익일배송) | B37: =SUMIFS('03_익일배송'!$E$4:$E$63,'03_익일배송'!$B$4:$B$63,2027,'03_익일배송'!$C$4:$C$63,12) -> 547.6476 | C37: =SUMIFS('03_익일배송'!$E$4:$E$63,'03_익일배송'!$B$4:$B$63,2028,'03_익일배송'!$C$4:$C$63,12) -> 684.27919 | D37: =SUMIFS('03_익일배송'!$E$4:$E$63,'03_익일배송'!$B$4:$B$63,2029,'03_익일배송'!$C$4:$C$63,12) -> 816.0724 | E37: =SUMIFS('03_익일배송'!$E$4:$E$63,'03_익일배송'!$B$4:$B$63,2030,'03_익일배송'!$C$4:$C$63,12) -> 943.19855 | F37: =SUMIFS('03_익일배송'!$E$4:$E$63,'03_익일배송'!$B$4:$B$63,2031,'03_익일배송'!$C$4:$C$63,12) -> 1065.8229
A38: ④ 회원 확대 (외국인) | B38: =SUMIFS('04_회원확대'!$E$4:$E$63,'04_회원확대'!$B$4:$B$63,2027,'04_회원확대'!$C$4:$C$63,12) -> 546.10526 | C38: =SUMIFS('04_회원확대'!$E$4:$E$63,'04_회원확대'!$B$4:$B$63,2028,'04_회원확대'!$C$4:$C$63,12) -> 678.03157 | D38: =SUMIFS('04_회원확대'!$E$4:$E$63,'04_회원확대'!$B$4:$B$63,2029,'04_회원확대'!$C$4:$C$63,12) -> 802.2564 | E38: =SUMIFS('04_회원확대'!$E$4:$E$63,'04_회원확대'!$B$4:$B$63,2030,'04_회원확대'!$C$4:$C$63,12) -> 919.22933 | F38: =SUMIFS('04_회원확대'!$E$4:$E$63,'04_회원확대'!$B$4:$B$63,2031,'04_회원확대'!$C$4:$C$63,12) -> 1029.3737
A40: 12월 회원수 (만명) | B40: 2027 | C40: 2028 | D40: 2029 | E40: 2030 | F40: 2031
A41: ① 현상유지 | B41: =SUMIFS('01_현상유지'!$N$4:$N$63,'01_현상유지'!$B$4:$B$63,2027,'01_현상유지'!$C$4:$C$63,12) -> 1329.5349 | C41: =SUMIFS('01_현상유지'!$N$4:$N$63,'01_현상유지'!$B$4:$B$63,2028,'01_현상유지'!$C$4:$C$63,12) -> 1543.1539 | D41: =SUMIFS('01_현상유지'!$N$4:$N$63,'01_현상유지'!$B$4:$B$63,2029,'01_현상유지'!$C$4:$C$63,12) -> 1698.608 | E41: =SUMIFS('01_현상유지'!$N$4:$N$63,'01_현상유지'!$B$4:$B$63,2030,'01_현상유지'!$C$4:$C$63,12) -> 1800.4431 | F41: =SUMIFS('01_현상유지'!$N$4:$N$63,'01_현상유지'!$B$4:$B$63,2031,'01_현상유지'!$C$4:$C$63,12) -> 1852.8727
